Workbook

Sheet Fomular
A1: Title | B1: Type | C1: Name | D1: Formula | E1: Source | F1: Note
A2: Forecast Revenue | B2: Fix cost | C2: Revenue for Fix cost project (Monthly) | D2: Contract revenue * (This month complete rate - Last month complete rate) | E2: Contract revenue: projects_contract.contract_revenue | F2: - Plan working day (month) = End date of the month - start date - (weekends + holidays) | G2: (if End date of the month < start date)
E3: Complete rate: fixcost_delivery_plan.complete_rate | F3: - Plan working day (month) = End date - start date of the month - (weekends + holidays) | G3: (if End date > First date of the month)
B4: Fix cost member | C4: Revenue for Fix cost member | D4: (working hours in month / (total member * working hours in month)) * Employee performance rate * Month Forecast Project revenue | E4: Employee Performance Rate: "tabProject User".performance_rate Month Forecast Project revenue: fixcost_delivery_plan.complete_rate
B5: Teambase member | C5: Revenue for Teambase member (Monthly) | D5: Headcount rate * Total forecast hour | E5: Employee rate: project_contract_headcount.rate | F5: Total forecast hour = 8 * Plan working day in month
B6: Teambase | C6: Revenue for Teambase project (Monthly) | D6: Sum(Revenue for Teambase Members)
B7: Division | C7: Revenue Division | D7: Sum (Revenue Fix cost project) + Sum (Revenue Teambase project)
B8: Company | C8: Revenue Company | D8: Sum (Revenue Division)
A9: Actual Revenue | B9: Fix cost | C9: Revenue for Fix cost project (Monthly) | D9: Contract revenue * (This month actual complete rate - Last month actual complete rate) | E9: actual complete rate: fixcost_delivery_plan.actual_complete_rate
B10: Teambase member | C10: Revenue for Teambase member (Monthly) | D10: Employee rate * Total actual hour | E10: Employee rate: project_contract_headcount.rate | F10: employee = "tabProject User".employee_code
B11: Teambase | C11: Revenue for Teambase project (Monthly) | D11: Sum (Revenue for Teambase member)
B12: Market | C12: Revenue for Market | D12: Sum (Revenue project by Market)
B13: All Market | C13: Revenue for All Market | D13: Sum (Revenue project all Market)
B14: Division | C14: Revenue Division | D14: Sum (Revenue Fix cost project) + Sum (Revenue Teambase Project)
B15: Company | C15: Revenue Company | D15: Sum (Revenue Division)
A16: Forecast cost | B16: Member | C16: Cost for member (Monthly) | D16: [Direct cost * (plan working day/total working day in month) + Project Bonus * (plan working day in month/total working day in month)
B17: Fix cost | C17: Cost for Fix cost project (Monthly) | D17: SUM(cost for fix cost member in month) + (project_package * plan_working_day/total_working_day_in_month) | E17: project_package: fixcost_project_package
B18: Teambase | C18: Cost for Teambase project (Monthly) | D18: SUM(cost for teambase member in month)
B19: Division | C19: Cost for Division | D19: SUM (cost for all project)
B20: Company | C20: Cost for company | D20: SUM (cost all division)
A21: Actual cost | B21: Member | C21: Cost for member (Monthly) | D21: [Direct cost * (actual working day/total working day in month) + Project Bonus * (actual working day in month/total working day in month) + Salary * (OT hour/8/total working day in month)] | E21: Direct cost: employee_direct_cost.direct_cost Project Bonus: employee_direct_cost.project_bonus
B22: Fix cost | C22: Cost for Fix cost | D22: SUM (cost for fix cost member in month)+ (project_package * actual_working_day_in_month/total_working_day_in_month)
B23: Teambase | C23: Cost for Teambase | D23: SUM (cost for teambase member in month) | E23: Member: "tabProject User".employee_code
B24: Project expense | C24: Cost for Project expense | D24: SUM (cost for fix cost project in month) + SUM (cost for teambase project in month)
B25: Human resource | C25: Cost for Human resource | D25: SUM (Headcount rate*total interview hour)
B26: Tranning, Resource pool | C26: Cost for Trainning, RP | D26: SUM (Headcount rate*total join in trainning/RP hour)
B27: Presale | C27: Cost for Presale | D27: SUM (Headcount rate*total join in Presale project hour)
B28: Division | C28: Cost for division | D28: SUM(cost for all project)
B29: Company | C29: Cost for company | D29: SUM (cost all division)
A30: Actual Revenue Percentage | B30: Fix cost | C30: Actual revenue percentage for fix cost project
B31: Teambase | C31: Actual revenue percentage for teambase project | D31: (Actual revenue teambase project in month/Actual revenue all project type in month)*100%
B32: Market | C32: Actual revenue percentage for market | D32: (Actual revenue market in month/Actual revenue all market in month)*100%
B33: Division | C33: Actual revenue percentage for division (monthly) | D33: (Actual revenue division in month/Actual revenue company in month)*100%
A34: Actual Cost Percentage | B34: Fix cost | C34: Actual cost percentage for fix cost project | D34: (Actual cost for fix cost project in month/Actual cost for all project type in month)*100%
B35: Teambase | C35: Actual cost percentage for teambase project | D35: (Actual cost for teambase project in month/Actual cost for all project type in month)*100%
B36: Project expense | C36: Actual cost percentage for project expense | D36: Actual cost percentage for fixcost + Actual cost percentage for teambase
B37: Human resource | C37: Actual cost percentage for human resource project | D37: (Actual cost for all human resource project/Actual cost all project type in month)*100%
B38: Training, RP | C38: Actual cost percentage for Training, RP project | D38: (Actual cost for all Training, RP project/Actual cost all project type in month)*100%
B39: Presale | C39: Actual cost percentage for _x0008_Presale project | D39: (Actual cost for all Presale project/Actual cost all project type in month)*100%
B40: Division | C40: Actual cost percentage for division (monthly) | D40: (Actual cost division in month/Actual cost company in month)*100%
...

Sheet 00. Revenue Actual
A1: REVENUE (ACTUAL) | AL1: Public Holiday | AM1: Observed
A3: Total Forecast Revenue by Divison | AH3: 1 | AI3: 44927 | AJ3: 44957 | AL3: New Year Holiday | AM3: 44928
A4: Division | B4: T1 | C4: T2 | D4: T3 | E4: T4 | F4: T5 | G4: T6 | H4: T7 | I4: T8 | J4: T9 | K4: T10 | L4: T11 | M4: T12 | N4: YEAR TOTAL | AH4: 2 | AI4: 44958 | AJ4: 44985 | AL4: Lunar New Year (Tet) Holidays | AM4: 44946
A5: Division 1 | B5: =SUMIFS(T14:T17,$A$14:$A$17,$A$5)+SUMIFS(T25:T34,$A$25:$A$34,$A$5) -> 0 | C5: =SUMIFS(U14:U17,$A$14:$A$17,$A$5)+SUMIFS(U25:U34,$A$25:$A$34,$A$5) -> 250052240 | D5: =SUMIFS(V14:V17,$A$14:$A$17,$A$5)+SUMIFS(V25:V34,$A$25:$A$34,$A$5) -> 1.000598e+08 | E5: =SUMIFS(W14:W17,$A$14:$A$17,$A$5)+SUMIFS(W25:W34,$A$25:$A$34,$A$5) -> 350047360 | F5: =SUMIFS(X14:X17,$A$14:$A$17,$A$5)+SUMIFS(X25:X34,$A$25:$A$34,$A$5) -> 1.000484e+08 | G5: =SUMIFS(Y14:Y17,$A$14:$A$17,$A$5)+SUMIFS(Y25:Y34,$A$25:$A$34,$A$5) -> 730055040 | H5: =SUMIFS(Z14:Z17,$A$14:$A$17,$A$5)+SUMIFS(Z25:Z34,$A$25:$A$34,$A$5) -> 2.650518e+08 | I5: =SUMIFS(AA14:AA17,$A$14:$A$17,$A$5)+SUMIFS(AA25:AA34,$A$25:$A$34,$A$5) -> 3.9755644e+08 | ... M5: =SUMIFS(AE14:AE17,$A$14:$A$17,$A$5)+SUMIFS(AE25:AE34,$A$25:$A$34,$A$5) -> 0 | N5: =SUM(B5:M5) -> 3120407360 | AH5: 3 | AI5: 44986 | AJ5: 45016 | AM5: 44947
A6: Division 2 | B6: =SUMIFS(T14:T17,$A$14:$A$17,$A$6)+SUMIFS(T25:T34,$A$25:$A$34,$A$6) -> 42532280 | C6: =SUMIFS(U14:U17,$A$14:$A$17,$A$6)+SUMIFS(U25:U34,$A$25:$A$34,$A$6) -> 85044160 | D6: =SUMIFS(V14:V17,$A$14:$A$17,$A$6)+SUMIFS(V25:V34,$A$25:$A$34,$A$6) -> 85045440 | E6: =SUMIFS(W14:W17,$A$14:$A$17,$A$6)+SUMIFS(W25:W34,$A$25:$A$34,$A$6) -> 42541960 | F6: =SUMIFS(X14:X17,$A$14:$A$17,$A$6)+SUMIFS(X25:X34,$A$25:$A$34,$A$6) -> 85044800 | G6: =SUMIFS(Y14:Y17,$A$14:$A$17,$A$6)+SUMIFS(Y25:Y34,$A$25:$A$34,$A$6) -> 42547040 | H6: =SUMIFS(Z14:Z17,$A$14:$A$17,$A$6)+SUMIFS(Z25:Z34,$A$25:$A$34,$A$6) -> 85045080 | I6: =SUMIFS(AA14:AA17,$A$14:$A$17,$A$6)+SUMIFS(AA25:AA34,$A$25:$A$34,$A$6) -> 1.275502e+08 | ... M6: =SUMIFS(AE14:AE17,$A$14:$A$17,$A$6)+SUMIFS(AE25:AE34,$A$25:$A$34,$A$6) -> 0 | N6: =SUM(B6:M6) -> 8.5043544e+08 | AH6: 4 | AI6: 45017 | AJ6: 45046 | AM6: 44948
A7: Division 3 | B7: =SUMIFS(T14:T17,$A$14:$A$17,$A$7)+SUMIFS(T25:T34,$A$25:$A$34,$A$7) -> 0 | C7: =SUMIFS(U14:U17,$A$14:$A$17,$A$7)+SUMIFS(U25:U34,$A$25:$A$34,$A$7) -> 183028080 | D7: =SUMIFS(V14:V17,$A$14:$A$17,$A$7)+SUMIFS(V25:V34,$A$25:$A$34,$A$7) -> 183049680 | E7: =SUMIFS(W14:W17,$A$14:$A$17,$A$7)+SUMIFS(W25:W34,$A$25:$A$34,$A$7) -> 152543200 | F7: =SUMIFS(X14:X17,$A$14:$A$17,$A$7)+SUMIFS(X25:X34,$A$25:$A$34,$A$7) -> 91500000 | G7: =SUMIFS(Y14:Y17,$A$14:$A$17,$A$7)+SUMIFS(Y25:Y34,$A$25:$A$34,$A$7) -> 0 | H7: =SUMIFS(Z14:Z17,$A$14:$A$17,$A$7)+SUMIFS(Z25:Z34,$A$25:$A$34,$A$7) -> 0 | I7: =SUMIFS(AA14:AA17,$A$14:$A$17,$A$7)+SUMIFS(AA25:AA34,$A$25:$A$34,$A$7) -> 0 | ... M7: =SUMIFS(AE14:AE17,$A$14:$A$17,$A$7)+SUMIFS(AE25:AE34,$A$25:$A$34,$A$7) -> 0 | N7: =SUM(B7:M7) -> 610120960 | AH7: 5 | AI7: 45047 | AJ7: 45077 | AM7: 44949
AH8: 6 | AI8: 45078 | AJ8: 45107 | AM8: 44950
A9: Project based = Total Contract Revenue * Actual Complete rate | AH9: 7 | AI9: 45108 | AJ9: 45138 | AM9: 44951
AH10: 8 | AI10: 45139 | AJ10: 45169 | AM10: 44952
A11: FC | B11: Project based (Fix cost) | AH11: 9 | AI11: 45170 | AJ11: 45199 | AL11: Hung Kings Commemoration Day | AM11: 45048
A12: Division | B12: Headcount | C12: Customer code | D12: Project code | E12: Start date | F12: End date | G12: Complete rate | S12: Total Contract Revenue | T12: Revenue T1 | U12: Revenue T2 | V12: Revenue T3 | W12: Revenue T4 | X12: Revenue T5 | Y12: Revenue T6 | Z12: Revenue T7 | AA12: Revenue T8 | AB12: Revenue T9 | AC12: Revenue T10 | AD12: Revenue T11 | AE12: Revenue T12 | AH12: 10 | AI12: 45200 | AJ12: 45230 | AL12: Victory Day | AM12: 45049
G13: T1 | H13: T2 | I13: T3 | J13: T4 | K13: T5 | L13: T6 | M13: T7 | N13: T8 | O13: T9 | P13: T10 | Q13: T11 | R13: T12 | AH13: 11 | AI13: 45231 | AJ13: 45260 | AL13: International Labor Day | AM13: 45047
A14: Division 1 | B14: 5 | C14: AN1 | D14: =$A$11&"_"&C14&"_"&"001" -> FC_AN1_001 | E14: 44958 | F14: 45130 | G14: 0 | H14: 0.25 | I14: 0.35 | J14: 0.7 | K14: 0.8 | L14: 1 | M14: 1 | N14: N/A | O14: N/A | P14: N/A | Q14: N/A | R14: N/A | S14: 1000000000 | T14: 0 | U14: =(H14-G14)*$S$14 -> 250000000 | V14: =(I14-H14)*$S$14 -> 1e+08 | W14: =(J14-I14)*$S$14 -> 350000000 | X14: =(K14-J14)*$S$14 -> 1e+08 | Y14: =(L14-K14)*$S$14 -> 2e+08 | Z14: =(M14-L14)*$S$14 -> 0 | AH14: 12 | AI14: 45261 | AJ14: 45291 | AL14: National Day | AM14: 45170
A15: Division 1 | B15: 11 | C15: AN1 | D15: =$A$11&"_"&C15&"_"&"001" -> FC_AN1_001 | E15: 45050 | F15: 45283 | G15: 0 | H15: N/A | I15: N/A | J15: N/A | K15: 0.2 | L15: 0.4 | M15: 0.5 | N15: 0.65 | O15: 0.8 | P15: 0.85 | Q15: 1 | R15: 1 | S15: 2650000000 | T15: 0 | Y15: =(L15-K15)*$S$15 -> 530000000 | Z15: =(M15-L15)*$S$15 -> 2.65e+08 | AA15: =(N15-M15)*$S$15 -> 3.975e+08 | AB15: =(O15-N15)*$S$15 -> 3.975e+08 | AC15: =(P15-O15)*$S$15 -> 1.325e+08 | AD15: =(Q15-P15)*$S$15 -> 3.975e+08 | AE15: =(R15-Q15)*$S$15 -> 0 | AM15: 45171
A16: Division 2 | B16: 7 | C16: AN2 | D16: =$A$11&"_"&C16&"_"&"001" -> FC_AN2_001 | E16: 44927 | F16: 45350 | G16: 0.05 | H16: 0.15 | I16: 0.25 | J16: 0.3 | K16: 0.4 | L16: 0.45 | M16: 0.55 | N16: 0.7 | O16: 0.75 | P16: 0.9 | Q16: 1 | R16: 1 | S16: 850000000 | T16: =G16*$S$16 -> 42500000 | U16: =(H16-G16)*$S$16 -> 85000000 | V16: =(I16-H16)*$S$16 -> 85000000 | W16: =(J16-I16)*$S$16 -> 42500000 | X16: =(K16-J16)*$S$16 -> 85000000 | Y16: =(L16-K16)*$S$16 -> 42500000 | Z16: =(M16-L16)*$S$16 -> 85000000 | AA16: =(N16-M16)*$S$16 -> 1.275e+08 | AB16: =(O16-N16)*$S$16 -> 42500000 | ... AE16: =(R16-Q16)*$S$16 -> 0 | AM16: 45172
A17: Division 3 | B17: 4 | C17: AN3 | D17: =$A$11&"_"&C17&"_"&"001" -> FC_AN3_001 | E17: 44970 | F17: 45074 | G17: 0 | H17: 0.3 | I17: 0.6 | J17: 0.85 | K17: 1 | L17: 0 | M17: 0 | N17: 0 | O17: 0 | P17: 0 | Q17: 0 | R17: 0 | S17: 610000000 | T17: 0 | U17: =(H17-G17)*$S$17 -> 183000000 | V17: =(I17-H17)*$S$17 -> 183000000 | W17: =(J17-I17)*$S$17 -> 152500000 | X17: =(K17-J17)*$S$17 -> 91500000 | AM17: 45173
A19: Team based = Employee rate * Actual effort
A21: TB | B21: Team based
A22: Division | B22: Employee code | C22: Customer code | D22: Project code | E22: Start date | F22: End date | G22: Employee Rate ($/hour) | H22: Effort (day/month) | T22: Revenue T1 | U22: Revenue T2 | V22: Revenue T3 | W22: Revenue T4 | X22: Revenue T5 | Y22: Revenue T6 | Z22: Revenue T7 | AA22: Revenue T8 | AB22: Revenue T9 | AC22: Revenue T10 | AD22: Revenue T11 | AE22: Revenue T12
H23: 1 | I23: 2 | J23: 3 | K23: 4 | L23: 5 | M23: 6 | N23: 7 | O23: 8 | P23: 9 | Q23: 10 | R23: 11 | S23: 12
H24: =NETWORKDAYS.INTL(VLOOKUP(H23,$AH$3:$AJ$14,2),VLOOKUP(H23,$AH$3:$AJ$14,3),"0000011",$AM$3:$AM$17) -> 16 | I24: =NETWORKDAYS.INTL(VLOOKUP(I23,$AH$3:$AJ$14,2),VLOOKUP(I23,$AH$3:$AJ$14,3),"0000011",$AM$3:$AM$17) -> 20 | J24: =NETWORKDAYS.INTL(VLOOKUP(J23,$AH$3:$AJ$14,2),VLOOKUP(J23,$AH$3:$AJ$14,3),"0000011",$AM$3:$AM$17) -> 23 | K24: =NETWORKDAYS.INTL(VLOOKUP(K23,$AH$3:$AJ$14,2),VLOOKUP(K23,$AH$3:$AJ$14,3),"0000011",$AM$3:$AM$17) -> 20 | L24: =NETWORKDAYS.INTL(VLOOKUP(L23,$AH$3:$AJ$14,2),VLOOKUP(L23,$AH$3:$AJ$14,3),"0000011",$AM$3:$AM$17) -> 20 | M24: =NETWORKDAYS.INTL(VLOOKUP(M23,$AH$3:$AJ$14,2),VLOOKUP(M23,$AH$3:$AJ$14,3),"0000011",$AM$3:$AM$17) -> 22 | N24: =NETWORKDAYS.INTL(VLOOKUP(N23,$AH$3:$AJ$14,2),VLOOKUP(N23,$AH$3:$AJ$14,3),"0000011",$AM$3:$AM$17) -> 21 | O24: =NETWORKDAYS.INTL(VLOOKUP(O23,$AH$3:$AJ$14,2),VLOOKUP(O23,$AH$3:$AJ$14,3),"0000011",$AM$3:$AM$17) -> 23 | ... S24: =NETWORKDAYS.INTL(VLOOKUP(S23,$AH$3:$AJ$14,2),VLOOKUP(S23,$AH$3:$AJ$14,3),"0000011",$AM$3:$AM$17) -> 21
A25: Division 1 | B25: SAVHN001 | C25: RAK | D25: =$A$21&"_"&C25&"_"&"001" -> TB_RAK_001 | E25: 44958 | F25: 45000 | G25: 30 | H25: 0 | I25: =NETWORKDAYS.INTL(E25,VLOOKUP($I$23,$AH$3:$AJ$14,3),"0000011",$AM$3:$AM$17) -> 20 | J25: =NETWORKDAYS.INTL(VLOOKUP(J23,$AH$3:$AJ$14,2),F25,"0000011",$AM$3:$AM$17) -> 11 | K25: 0 | L25: 0 | M25: 0 | N25: 0 | O25: 0 | P25: 0 | Q25: 0 | R25: 0 | S25: 0 | T25: =H25*$G$25*8 -> 0 | U25: =I25*$G$25*8 -> 4800 | V25: =J25*$G$25*8 -> 2640 | W25: =K25*$G$25*8 -> 0 | X25: =L25*$G$25*8 -> 0 | Y25: =M25*$G$25*8 -> 0 | Z25: =N25*$G$25*8 -> 0 | AA25: =O25*$G$25*8 -> 0 | ... AE25: =S25*$G$25*8 -> 0
A26: Division 1 | B26: SAVHN002 | C26: RAK | D26: =$A$21&"_"&C26&"_"&"001" -> TB_RAK_001 | E26: 44958 | F26: 45194 | G26: 50 | H26: 0 | I26: 18 | J26: =$J$24 -> 23 | K26: =$K$24 -> 20 | L26: =$L$24 -> 20 | M26: 21 | N26: 20 | O26: =$O$24 -> 23 | P26: =NETWORKDAYS.INTL(VLOOKUP($P$23,$AH$3:$AJ$14,2),F26,"0000011",$AM$3:$AM$17) -> 15 | Q26: 0 | R26: 0 | S26: 0 | T26: =H26*$G$26*8 -> 0 | U26: =I26*$G$26*8 -> 7200 | V26: =J26*$G$26*8 -> 9200 | W26: =K26*$G$26*8 -> 8000 | X26: =L26*$G$26*8 -> 8000 | Y26: =M26*$G$26*8 -> 8400 | Z26: =N26*$G$26*8 -> 8000 | AA26: =O26*$G$26*8 -> 9200 | ... AE26: =S26*$G$26*8 -> 0
A27: Division 1 | B27: SAVHN003 | C27: RAK | D27: =$A$21&"_"&C27&"_"&"001" -> TB_RAK_001 | E27: 44958 | F27: 45194 | G27: 75 | H27: 0 | I27: =NETWORKDAYS.INTL(E27,VLOOKUP($I$23,$AH$3:$AJ$14,3),"0000011",$AM$3:$AM$17) -> 20 | J27: =$J$24 -> 23 | K27: =$K$24 -> 20 | L27: 18 | M27: =$M$24 -> 22 | N27: =$N$24 -> 21 | O27: =$O$24 -> 23 | P27: =NETWORKDAYS.INTL(VLOOKUP($P$23,$AH$3:$AJ$14,2),F27,"0000011",$AM$3:$AM$17) -> 15 | Q27: 0 | R27: 0 | S27: 0 | T27: =H27*$G$27*8 -> 0 | U27: =I27*$G$27*8 -> 12000 | V27: =J27*$G$27*8 -> 13800 | W27: =K27*$G$27*8 -> 12000 | X27: =L27*$G$27*8 -> 10800 | Y27: =M27*$G$27*8 -> 13200 | Z27: =N27*$G$27*8 -> 12600 | AA27: =O27*$G$27*8 -> 13800 | ... AE27: =S27*$G$27*8 -> 0
A28: Division 1 | B28: SAVHN004 | C28: RAK | D28: =$A$21&"_"&C28&"_"&"001" -> TB_RAK_001 | E28: 44958 | F28: 45194 | G28: 90 | H28: 0 | I28: 17 | J28: =$J$24 -> 23 | K28: 18 | L28: =$L$24 -> 20 | M28: =$M$24 -> 22 | N28: 20 | O28: 22 | P28: 14 | Q28: 0 | R28: 0 | S28: 0 | T28: =H28*$G$28*8 -> 0 | U28: =I28*$G$28*8 -> 12240 | V28: =J28*$G$28*8 -> 16560 | W28: =K28*$G$28*8 -> 12960 | X28: =L28*$G$28*8 -> 14400 | Y28: =M28*$G$28*8 -> 15840 | Z28: =N28*$G$28*8 -> 14400 | AA28: =O28*$G$28*8 -> 15840 | ... AE28: =S28*$G$28*8 -> 0
A29: Division 1 | B29: SAVHN005 | C29: RAK | D29: =$A$21&"_"&C29&"_"&"001" -> TB_RAK_001 | E29: 44958 | F29: 45194 | G29: 100 | H29: 0 | I29: =NETWORKDAYS.INTL(E29,VLOOKUP($I$23,$AH$3:$AJ$14,3),"0000011",$AM$3:$AM$17) -> 20 | J29: 22 | K29: 18 | L29: 19 | M29: =$M$24 -> 22 | N29: =$N$24 -> 21 | O29: 22 | P29: 14 | Q29: 0 | R29: 0 | S29: 0 | T29: =H29*$G$29*8 -> 0 | U29: =I29*$G$29*8 -> 16000 | V29: =J29*$G$29*8 -> 17600 | W29: =K29*$G$29*8 -> 14400 | X29: =L29*$G$29*8 -> 15200 | Y29: =M29*$G$29*8 -> 17600 | Z29: =N29*$G$29*8 -> 16800 | AA29: =O29*$G$29*8 -> 17600 | ... AE29: =S29*$G$29*8 -> 0
A30: Division 2 | B30: SAVHN006 | C30: BKT | D30: =$A$21&"_"&C30&"_"&"001" -> TB_BKT_001 | E30: 44927 | F30: 45227 | G30: 80 | H30: 14 | I30: 19 | J30: 21 | K30: 17 | L30: =$L$24 -> 20 | M30: 21 | N30: 19 | O30: 22 | P30: 18 | Q30: 19 | R30: 0 | S30: 0 | T30: =H30*$G$30*8 -> 8960 | U30: =I30*$G$30*8 -> 12160 | V30: =J30*$G$30*8 -> 13440 | W30: =K30*$G$30*8 -> 10880 | X30: =L30*$G$30*8 -> 12800 | Y30: =M30*$G$30*8 -> 13440 | Z30: =N30*$G$30*8 -> 12160 | AA30: =O30*$G$30*8 -> 14080 | ... AE30: =S30*$G$30*8 -> 0
A31: Division 2 | B31: SAVHN007 | C31: BKT | D31: =$A$21&"_"&C31&"_"&"001" -> TB_BKT_001 | E31: 44927 | F31: 45227 | G31: 85 | H31: 14 | I31: =$I$24 -> 20 | J31: 20 | K31: 20 | L31: 20 | M31: 21 | N31: 20 | O31: 22 | P31: =$P$24 -> 19 | Q31: 19 | R31: 0 | S31: 0 | T31: =H31*$G$31*8 -> 9520 | U31: =I31*$G$31*8 -> 13600 | V31: =J31*$G$31*8 -> 13600 | W31: =K31*$G$31*8 -> 13600 | X31: =L31*$G$31*8 -> 13600 | Y31: =M31*$G$31*8 -> 14280 | Z31: =N31*$G$31*8 -> 13600 | AA31: =O31*$G$31*8 -> 14960 | ... AE31: =S31*$G$31*8 -> 0
A32: Division 2 | B32: SAVHN008 | C32: BKT | D32: =$A$21&"_"&C32&"_"&"001" -> TB_BKT_001 | E32: 44927 | F32: 45227 | G32: 115 | H32: 15 | I32: =$I$24 -> 20 | J32: 20 | K32: 19 | L32: =$L$24 -> 20 | M32: 21 | N32: =$N$24 -> 21 | O32: =$O$24 -> 23 | P32: =$P$24 -> 19 | Q32: 19 | R32: 0 | S32: 0 | T32: =H32*$G$32*8 -> 13800 | U32: =I32*$G$32*8 -> 18400 | V32: =J32*$G$32*8 -> 18400 | W32: =K32*$G$32*8 -> 17480 | X32: =L32*$G$32*8 -> 18400 | Y32: =M32*$G$32*8 -> 19320 | Z32: =N32*$G$32*8 -> 19320 | AA32: =O32*$G$32*8 -> 21160 | ... AE32: =S32*$G$32*8 -> 0
A33: Division 3 | B33: SAVHN009 | C33: OMI | D33: =$A$21&"_"&C33&"_"&"001" -> TB_OMI_001 | E33: 44967 | F33: 45044 | G33: 120 | H33: 0 | I33: =NETWORKDAYS.INTL(E33,VLOOKUP($I$23,$AH$3:$AJ$14,3),"0000011",$AM$3:$AM$17) -> 13 | J33: =$J$24 -> 23 | K33: =NETWORKDAYS.INTL(VLOOKUP($K$23,$AH$3:$AJ$14,2),F33,"0000011",$AM$3:$AM$17) -> 20 | L33: 0 | M33: 0 | N33: 0 | O33: 0 | P33: 0 | Q33: 0 | R33: 0 | S33: 0 | T33: =H33*$G$33*8 -> 0 | U33: =I33*$G$33*8 -> 12480 | V33: =J33*$G$33*8 -> 22080 | W33: =K33*$G$33*8 -> 19200 | X33: =L33*$G$33*8 -> 0 | Y33: =M33*$G$33*8 -> 0 | Z33: =N33*$G$33*8 -> 0 | AA33: =O33*$G$33*8 -> 0 | ... AE33: =S33*$G$33*8 -> 0
A34: Division 3 | B34: SAVHN010 | C34: OMI | D34: =$A$21&"_"&C34&"_"&"001" -> TB_OMI_001 | E34: 44967 | F34: 45044 | G34: 150 | H34: 0 | I34: =NETWORKDAYS.INTL(E34,VLOOKUP($I$23,$AH$3:$AJ$14,3),"0000011",$AM$3:$AM$17) -> 13 | J34: =$J$24 -> 23 | K34: =NETWORKDAYS.INTL(VLOOKUP($K$23,$AH$3:$AJ$14,2),F34,"0000011",$AM$3:$AM$17) -> 20 | L34: 0 | M34: 0 | N34: 0 | O34: 0 | P34: 0 | Q34: 0 | R34: 0 | S34: 0 | T34: =H34*$G$34*8 -> 0 | U34: =I34*$G$34*8 -> 15600 | V34: =J34*$G$34*8 -> 27600 | W34: =K34*$G$34*8 -> 24000 | X34: =L34*$G$34*8 -> 0 | Y34: =M34*$G$34*8 -> 0 | Z34: =N34*$G$34*8 -> 0 | AA34: =O34*$G$34*8 -> 0 | ... AE34: =S34*$G$34*8 -> 0
C37: Projecttype_mãKH_mã dự án (text/# - tối đa 3 ký tự)
C38: 2_3_3
C40: [Fix cost] Revenue by member: = effort member/total effort * performance rate * monthly revenue
C42: busy rate tính trên effort (h): logged work
B45: Revenue Division = Revenue Fix cost + Revenue Teambase
B46: Revenue Fix cost (Monthly) =

Sheet 01. Revenue Forecast
A1: REVENUE (_x000D_FORECAST)
A3: Total Forecast Revenue by Divison | AH3: 1 | AI3: 44927 | AJ3: 44957 | AL3: New Year Holiday | AM3: 44928
A4: Division | B4: T1 | C4: T2 | D4: T3 | E4: T4 | F4: T5 | G4: T6 | H4: T7 | I4: T8 | J4: T9 | K4: T10 | L4: T11 | M4: T12 | N4: YEAR TOTAL | AH4: 2 | AI4: 44958 | AJ4: 44985 | AL4: Lunar New Year (Tet) Holidays | AM4: 44946
A5: Division 1 | B5: =SUMIFS(T14:T17,$A$14:$A$17,$A$5)+SUMIFS(T25:T34,$A$25:$A$34,$A$5) -> 0 | C5: =SUMIFS(U14:U17,$A$14:$A$17,$A$5)+SUMIFS(U25:U34,$A$25:$A$34,$A$5) -> 300055200 | D5: =SUMIFS(V14:V17,$A$14:$A$17,$A$5)+SUMIFS(V25:V34,$A$25:$A$34,$A$5) -> 1.000606e+08 | E5: =SUMIFS(W14:W17,$A$14:$A$17,$A$5)+SUMIFS(W25:W34,$A$25:$A$34,$A$5) -> 3.000504e+08 | F5: =SUMIFS(X14:X17,$A$14:$A$17,$A$5)+SUMIFS(X25:X34,$A$25:$A$34,$A$5) -> 1.500504e+08 | G5: =SUMIFS(Y14:Y17,$A$14:$A$17,$A$5)+SUMIFS(Y25:Y34,$A$25:$A$34,$A$5) -> 580055440 | H5: =SUMIFS(Z14:Z17,$A$14:$A$17,$A$5)+SUMIFS(Z25:Z34,$A$25:$A$34,$A$5) -> 3.6505292e+08 | I5: =SUMIFS(AA14:AA17,$A$14:$A$17,$A$5)+SUMIFS(AA25:AA34,$A$25:$A$34,$A$5) -> 3.9755796e+08 | ... M5: =SUMIFS(AE14:AE17,$A$14:$A$17,$A$5)+SUMIFS(AE25:AE34,$A$25:$A$34,$A$5) -> 1.325e+08 | N5: =SUM(B5:M5) -> 3120420720 | AH5: 3 | AI5: 44986 | AJ5: 45016 | AM5: 44947
A6: Division 2 | B6: =SUMIFS(T14:T17,$A$14:$A$17,$A$6)+SUMIFS(T25:T34,$A$25:$A$34,$A$6) -> 42535840 | C6: =SUMIFS(U14:U17,$A$14:$A$17,$A$6)+SUMIFS(U25:U34,$A$25:$A$34,$A$6) -> 42544800 | D6: =SUMIFS(V14:V17,$A$14:$A$17,$A$6)+SUMIFS(V25:V34,$A$25:$A$34,$A$6) -> 85051520 | E6: =SUMIFS(W14:W17,$A$14:$A$17,$A$6)+SUMIFS(W25:W34,$A$25:$A$34,$A$6) -> 85044800 | F6: =SUMIFS(X14:X17,$A$14:$A$17,$A$6)+SUMIFS(X25:X34,$A$25:$A$34,$A$6) -> 42544800 | G6: =SUMIFS(Y14:Y17,$A$14:$A$17,$A$6)+SUMIFS(Y25:Y34,$A$25:$A$34,$A$6) -> 85049280 | H6: =SUMIFS(Z14:Z17,$A$14:$A$17,$A$6)+SUMIFS(Z25:Z34,$A$25:$A$34,$A$6) -> 85047040 | I6: =SUMIFS(AA14:AA17,$A$14:$A$17,$A$6)+SUMIFS(AA25:AA34,$A$25:$A$34,$A$6) -> 85051520 | ... M6: =SUMIFS(AE14:AE17,$A$14:$A$17,$A$6)+SUMIFS(AE25:AE34,$A$25:$A$34,$A$6) -> 42500000 | N6: =SUM(B6:M6) -> 850456960 | AH6: 4 | AI6: 45017 | AJ6: 45046 | AM6: 44948
A7: Division 3 | B7: =SUMIFS(T14:T17,$A$14:$A$17,$A$7)+SUMIFS(T25:T34,$A$25:$A$34,$A$7) -> 0 | C7: =SUMIFS(U14:U17,$A$14:$A$17,$A$7)+SUMIFS(U25:U34,$A$25:$A$34,$A$7) -> 183028080 | D7: =SUMIFS(V14:V17,$A$14:$A$17,$A$7)+SUMIFS(V25:V34,$A$25:$A$34,$A$7) -> 183049680 | E7: =SUMIFS(W14:W17,$A$14:$A$17,$A$7)+SUMIFS(W25:W34,$A$25:$A$34,$A$7) -> 152543200 | F7: =SUMIFS(X14:X17,$A$14:$A$17,$A$7)+SUMIFS(X25:X34,$A$25:$A$34,$A$7) -> 91500000 | G7: =SUMIFS(Y14:Y17,$A$14:$A$17,$A$7)+SUMIFS(Y25:Y34,$A$25:$A$34,$A$7) -> 0 | H7: =SUMIFS(Z14:Z17,$A$14:$A$17,$A$7)+SUMIFS(Z25:Z34,$A$25:$A$34,$A$7) -> 0 | I7: =SUMIFS(AA14:AA17,$A$14:$A$17,$A$7)+SUMIFS(AA25:AA34,$A$25:$A$34,$A$7) -> 0 | ... M7: =SUMIFS(AE14:AE17,$A$14:$A$17,$A$7)+SUMIFS(AE25:AE34,$A$25:$A$34,$A$7) -> 0 | N7: =SUM(B7:M7) -> 610120960 | AH7: 5 | AI7: 45047 | AJ7: 45077 | AM7: 44949
AH8: 6 | AI8: 45078 | AJ8: 45107 | AM8: 44950
A9: [Project Based] Revenue/month = Total Contract Revenue * Monthly Expected Complete Rate | AH9: 7 | AI9: 45108 | AJ9: 45138 | AM9: 44951
AH10: 8 | AI10: 45139 | AJ10: 45169 | AM10: 44952
A11: FC | B11: Project based (Fix cost) | AH11: 9 | AI11: 45170 | AJ11: 45199 | AL11: Hung Kings Commemoration Day | AM11: 45048
A12: Division | B12: Headcount | C12: Customer code | D12: Project code | E12: Start date | F12: End date | G12: Complete rate | S12: Total Contract Revenue | T12: Revenue T1 | U12: Revenue T2 | V12: Revenue T3 | W12: Revenue T4 | X12: Revenue T5 | Y12: Revenue T6 | Z12: Revenue T7 | AA12: Revenue T8 | AB12: Revenue T9 | AC12: Revenue T10 | AD12: Revenue T11 | AE12: Revenue T12 | AH12: 10 | AI12: 45200 | AJ12: 45230 | AL12: Victory Day | AM12: 45049
G13: T1 | H13: T2 | I13: T3 | J13: T4 | K13: T5 | L13: T6 | M13: T7 | N13: T8 | O13: T9 | P13: T10 | Q13: T11 | R13: T12 | AH13: 11 | AI13: 45231 | AJ13: 45260 | AL13: International Labor Day | AM13: 45047
A14: Division 1 | B14: 5 | C14: AN1 | D14: =$A$11&"_"&C14&"_"&"001" -> FC_AN1_001 | E14: 44958 | F14: 45130 | G14: 0 | H14: 0.3 | I14: 0.4 | J14: 0.7 | K14: 0.85 | L14: 0.9 | M14: 1 | N14: N/A | O14: N/A | P14: N/A | Q14: N/A | R14: N/A | S14: 1000000000 | T14: 0 | U14: =(H14-G14)*$S$14 -> 300000000 | V14: =(I14-H14)*$S$14 -> 1e+08 | W14: =(J14-I14)*$S$14 -> 3e+08 | X14: =(K14-J14)*$S$14 -> 1.5e+08 | Y14: =(L14-K14)*$S$14 -> 50000000 | Z14: =(M14-L14)*$S$14 -> 1e+08 | AH14: 12 | AI14: 45261 | AJ14: 45291 | AL14: National Day | AM14: 45170
A15: Division 1 | B15: 11 | C15: AN1 | D15: =$A$11&"_"&C15&"_"&"001" -> FC_AN1_001 | E15: 45050 | F15: 45283 | G15: 0 | H15: N/A | I15: N/A | J15: N/A | K15: 0.2 | L15: 0.4 | M15: 0.5 | N15: 0.65 | O15: 0.75 | P15: 0.85 | Q15: 0.95 | R15: 1 | S15: 2650000000 | T15: 0 | Y15: =(L15-K15)*$S$15 -> 530000000 | Z15: =(M15-L15)*$S$15 -> 2.65e+08 | AA15: =(N15-M15)*$S$15 -> 3.975e+08 | AB15: =(O15-N15)*$S$15 -> 2.65e+08 | AC15: =(P15-O15)*$S$15 -> 2.65e+08 | AD15: =(Q15-P15)*$S$15 -> 2.65e+08 | AE15: =(R15-Q15)*$S$15 -> 1.325e+08 | AM15: 45171
A16: Division 2 | B16: 7 | C16: AN2 | D16: =$A$11&"_"&C16&"_"&"001" -> FC_AN2_001 | E16: 44927 | F16: 45350 | G16: 0.05 | H16: 0.1 | I16: 0.2 | J16: 0.3 | K16: 0.35 | L16: 0.45 | M16: 0.55 | N16: 0.65 | O16: 0.75 | P16: 0.85 | Q16: 0.95 | R16: 1 | S16: 850000000 | T16: =G16*$S$16 -> 42500000 | U16: =(H16-G16)*$S$16 -> 42500000 | V16: =(I16-H16)*$S$16 -> 85000000 | W16: =(J16-I16)*$S$16 -> 85000000 | X16: =(K16-J16)*$S$16 -> 42500000 | Y16: =(L16-K16)*$S$16 -> 85000000 | Z16: =(M16-L16)*$S$16 -> 85000000 | AA16: =(N16-M16)*$S$16 -> 85000000 | AB16: =(O16-N16)*$S$16 -> 85000000 | ... AE16: =(R16-Q16)*$S$16 -> 42500000 | AM16: 45172
A17: Division 3 | B17: 4 | C17: AN3 | D17: =$A$11&"_"&C17&"_"&"001" -> FC_AN3_001 | E17: 44970 | F17: 45074 | G17: 0 | H17: 0.3 | I17: 0.6 | J17: 0.85 | K17: 1 | L17: 0 | M17: 0 | N17: 0 | O17: 0 | P17: 0 | Q17: 0 | R17: 0 | S17: 610000000 | T17: 0 | U17: =(H17-G17)*$S$17 -> 183000000 | V17: =(I17-H17)*$S$17 -> 183000000 | W17: =(J17-I17)*$S$17 -> 152500000 | X17: =(K17-J17)*$S$17 -> 91500000 | AM17: 45173
A19: [Team based] Revenue/month = Employee Rate * Monthly Effort
A21: TB | B21: Team based
A22: Division | B22: Employee code | C22: Customer code | D22: Project code | E22: Start date | F22: End date | G22: Employee Rate ($/hour) | H22: Effort (day/month) | T22: Revenue T1 | U22: Revenue T2 | V22: Revenue T3 | W22: Revenue T4 | X22: Revenue T5 | Y22: Revenue T6 | Z22: Revenue T7 | AA22: Revenue T8 | AB22: Revenue T9 | AC22: Revenue T10 | AD22: Revenue T11 | AE22: Revenue T12
H23: 1 | I23: 2 | J23: 3 | K23: 4 | L23: 5 | M23: 6 | N23: 7 | O23: 8 | P23: 9 | Q23: 10 | R23: 11 | S23: 12
H24: =NETWORKDAYS.INTL(VLOOKUP(H23,$AH$3:$AJ$14,2),VLOOKUP(H23,$AH$3:$AJ$14,3),"0000011",$AM$3:$AM$17) -> 16 | I24: =NETWORKDAYS.INTL(VLOOKUP(I23,$AH$3:$AJ$14,2),VLOOKUP(I23,$AH$3:$AJ$14,3),"0000011",$AM$3:$AM$17) -> 20 | J24: =NETWORKDAYS.INTL(VLOOKUP(J23,$AH$3:$AJ$14,2),VLOOKUP(J23,$AH$3:$AJ$14,3),"0000011",$AM$3:$AM$17) -> 23 | K24: =NETWORKDAYS.INTL(VLOOKUP(K23,$AH$3:$AJ$14,2),VLOOKUP(K23,$AH$3:$AJ$14,3),"0000011",$AM$3:$AM$17) -> 20 | L24: =NETWORKDAYS.INTL(VLOOKUP(L23,$AH$3:$AJ$14,2),VLOOKUP(L23,$AH$3:$AJ$14,3),"0000011",$AM$3:$AM$17) -> 20 | M24: =NETWORKDAYS.INTL(VLOOKUP(M23,$AH$3:$AJ$14,2),VLOOKUP(M23,$AH$3:$AJ$14,3),"0000011",$AM$3:$AM$17) -> 22 | N24: =NETWORKDAYS.INTL(VLOOKUP(N23,$AH$3:$AJ$14,2),VLOOKUP(N23,$AH$3:$AJ$14,3),"0000011",$AM$3:$AM$17) -> 21 | O24: =NETWORKDAYS.INTL(VLOOKUP(O23,$AH$3:$AJ$14,2),VLOOKUP(O23,$AH$3:$AJ$14,3),"0000011",$AM$3:$AM$17) -> 23 | ... S24: =NETWORKDAYS.INTL(VLOOKUP(S23,$AH$3:$AJ$14,2),VLOOKUP(S23,$AH$3:$AJ$14,3),"0000011",$AM$3:$AM$17) -> 21
A25: Division 1 | B25: SAVHN001 | C25: RAK | D25: =$A$21&"_"&C25&"_"&"001" -> TB_RAK_001 | E25: 44958 | F25: 45000 | G25: 30 | H25: 0 | I25: =NETWORKDAYS.INTL(E25,VLOOKUP($I$23,$AH$3:$AJ$14,3),"0000011",$AM$3:$AM$17) -> 20 | J25: =NETWORKDAYS.INTL(VLOOKUP(J23,$AH$3:$AJ$14,2),F25,"0000011",$AM$3:$AM$17) -> 11 | K25: 0 | L25: 0 | M25: 0 | N25: 0 | O25: 0 | P25: 0 | Q25: 0 | R25: 0 | S25: 0 | T25: =H25*$G$25*8 -> 0 | U25: =I25*$G$25*8 -> 4800 | V25: =J25*$G$25*8 -> 2640 | W25: =K25*$G$25*8 -> 0 | X25: =L25*$G$25*8 -> 0 | Y25: =M25*$G$25*8 -> 0 | Z25: =N25*$G$25*8 -> 0 | AA25: =O25*$G$25*8 -> 0 | ... AE25: =S25*$G$25*8 -> 0
A26: Division 1 | B26: SAVHN002 | C26: RAK | D26: =$A$21&"_"&C26&"_"&"001" -> TB_RAK_001 | E26: 44958 | F26: 45194 | G26: 50 | H26: 0 | I26: =NETWORKDAYS.INTL(E26,VLOOKUP($I$23,$AH$3:$AJ$14,3),"0000011",$AM$3:$AM$17) -> 20 | J26: =$J$24 -> 23 | K26: =$K$24 -> 20 | L26: =$L$24 -> 20 | M26: =$M$24 -> 22 | N26: =$N$24 -> 21 | O26: =$O$24 -> 23 | P26: =NETWORKDAYS.INTL(VLOOKUP($P$23,$AH$3:$AJ$14,2),F26,"0000011",$AM$3:$AM$17) -> 15 | Q26: 0 | R26: 0 | S26: 0 | T26: =H26*$G$26*8 -> 0 | U26: =I26*$G$26*8 -> 8000 | V26: =J26*$G$26*8 -> 9200 | W26: =K26*$G$26*8 -> 8000 | X26: =L26*$G$26*8 -> 8000 | Y26: =M26*$G$26*8 -> 8800 | Z26: =N26*$G$26*8 -> 8400 | AA26: =O26*$G$26*8 -> 9200 | ... AE26: =S26*$G$26*8 -> 0
A27: Division 1 | B27: SAVHN003 | C27: RAK | D27: =$A$21&"_"&C27&"_"&"001" -> TB_RAK_001 | E27: 44958 | F27: 45194 | G27: 75 | H27: 0 | I27: =NETWORKDAYS.INTL(E27,VLOOKUP($I$23,$AH$3:$AJ$14,3),"0000011",$AM$3:$AM$17) -> 20 | J27: =$J$24 -> 23 | K27: =$K$24 -> 20 | L27: =$L$24 -> 20 | M27: =$M$24 -> 22 | N27: =$N$24 -> 21 | O27: =$O$24 -> 23 | P27: =NETWORKDAYS.INTL(VLOOKUP($P$23,$AH$3:$AJ$14,2),F27,"0000011",$AM$3:$AM$17) -> 15 | Q27: 0 | R27: 0 | S27: 0 | T27: =H27*$G$27*8 -> 0 | U27: =I27*$G$27*8 -> 12000 | V27: =J27*$G$27*8 -> 13800 | W27: =K27*$G$27*8 -> 12000 | X27: =L27*$G$27*8 -> 12000 | Y27: =M27*$G$27*8 -> 13200 | Z27: =N27*$G$27*8 -> 12600 | AA27: =O27*$G$27*8 -> 13800 | ... AE27: =S27*$G$27*8 -> 0
A28: Division 1 | B28: SAVHN004 | C28: RAK | D28: =$A$21&"_"&C28&"_"&"001" -> TB_RAK_001 | E28: 44958 | F28: 45194 | G28: 90 | H28: 0 | I28: =NETWORKDAYS.INTL(E28,VLOOKUP($I$23,$AH$3:$AJ$14,3),"0000011",$AM$3:$AM$17) -> 20 | J28: =$J$24 -> 23 | K28: =$K$24 -> 20 | L28: =$L$24 -> 20 | M28: =$M$24 -> 22 | N28: =$N$24 -> 21 | O28: =$O$24 -> 23 | P28: =NETWORKDAYS.INTL(VLOOKUP($P$23,$AH$3:$AJ$14,2),F28,"0000011",$AM$3:$AM$17) -> 15 | Q28: 0 | R28: 0 | S28: 0 | T28: =H28*$G$28*8 -> 0 | U28: =I28*$G$28*8 -> 14400 | V28: =J28*$G$28*8 -> 16560 | W28: =K28*$G$28*8 -> 14400 | X28: =L28*$G$28*8 -> 14400 | Y28: =M28*$G$28*8 -> 15840 | Z28: =N28*$G$28*8 -> 15120 | AA28: =O28*$G$28*8 -> 16560 | ... AE28: =S28*$G$28*8 -> 0
A29: Division 1 | B29: SAVHN005 | C29: RAK | D29: =$A$21&"_"&C29&"_"&"001" -> TB_RAK_001 | E29: 44958 | F29: 45194 | G29: 100 | H29: 0 | I29: =NETWORKDAYS.INTL(E29,VLOOKUP($I$23,$AH$3:$AJ$14,3),"0000011",$AM$3:$AM$17) -> 20 | J29: =$J$24 -> 23 | K29: =$K$24 -> 20 | L29: =$L$24 -> 20 | M29: =$M$24 -> 22 | N29: =$N$24 -> 21 | O29: =$O$24 -> 23 | P29: =NETWORKDAYS.INTL(VLOOKUP($P$23,$AH$3:$AJ$14,2),F29,"0000011",$AM$3:$AM$17) -> 15 | Q29: 0 | R29: 0 | S29: 0 | T29: =H29*$G$29*8 -> 0 | U29: =I29*$G$29*8 -> 16000 | V29: =J29*$G$29*8 -> 18400 | W29: =K29*$G$29*8 -> 16000 | X29: =L29*$G$29*8 -> 16000 | Y29: =M29*$G$29*8 -> 17600 | Z29: =N29*$G$29*8 -> 16800 | AA29: =O29*$G$29*8 -> 18400 | ... AE29: =S29*$G$29*8 -> 0
A30: Division 2 | B30: SAVHN006 | C30: BKT | D30: =$A$21&"_"&C30&"_"&"001" -> TB_BKT_001 | E30: 44927 | F30: 45227 | G30: 80 | H30: =$H$24 -> 16 | I30: =$I$24 -> 20 | J30: =$J$24 -> 23 | K30: =$K$24 -> 20 | L30: =$L$24 -> 20 | M30: =$M$24 -> 22 | N30: =$N$24 -> 21 | O30: =$O$24 -> 23 | P30: =$P$24 -> 19 | Q30: =NETWORKDAYS.INTL(VLOOKUP($Q$23,$AH$3:$AJ$14,2),F30,"0000011",$AM$3:$AM$17) -> 20 | R30: 0 | S30: 0 | T30: =H30*$G$30*8 -> 10240 | U30: =I30*$G$30*8 -> 12800 | V30: =J30*$G$30*8 -> 14720 | W30: =K30*$G$30*8 -> 12800 | X30: =L30*$G$30*8 -> 12800 | Y30: =M30*$G$30*8 -> 14080 | Z30: =N30*$G$30*8 -> 13440 | AA30: =O30*$G$30*8 -> 14720 | ... AE30: =S30*$G$30*8 -> 0
A31: Division 2 | B31: SAVHN007 | C31: BKT | D31: =$A$21&"_"&C31&"_"&"001" -> TB_BKT_001 | E31: 44927 | F31: 45227 | G31: 85 | H31: =$H$24 -> 16 | I31: =$I$24 -> 20 | J31: =$J$24 -> 23 | K31: =$K$24 -> 20 | L31: =$L$24 -> 20 | M31: =$M$24 -> 22 | N31: =$N$24 -> 21 | O31: =$O$24 -> 23 | P31: =$P$24 -> 19 | Q31: =NETWORKDAYS.INTL(VLOOKUP($Q$23,$AH$3:$AJ$14,2),F31,"0000011",$AM$3:$AM$17) -> 20 | R31: 0 | S31: 0 | T31: =H31*$G$31*8 -> 10880 | U31: =I31*$G$31*8 -> 13600 | V31: =J31*$G$31*8 -> 15640 | W31: =K31*$G$31*8 -> 13600 | X31: =L31*$G$31*8 -> 13600 | Y31: =M31*$G$31*8 -> 14960 | Z31: =N31*$G$31*8 -> 14280 | AA31: =O31*$G$31*8 -> 15640 | ... AE31: =S31*$G$31*8 -> 0
A32: Division 2 | B32: SAVHN008 | C32: BKT | D32: =$A$21&"_"&C32&"_"&"001" -> TB_BKT_001 | E32: 44927 | F32: 45227 | G32: 115 | H32: =$H$24 -> 16 | I32: =$I$24 -> 20 | J32: =$J$24 -> 23 | K32: =$K$24 -> 20 | L32: =$L$24 -> 20 | M32: =$M$24 -> 22 | N32: =$N$24 -> 21 | O32: =$O$24 -> 23 | P32: =$P$24 -> 19 | Q32: =NETWORKDAYS.INTL(VLOOKUP($Q$23,$AH$3:$AJ$14,2),F32,"0000011",$AM$3:$AM$17) -> 20 | R32: 0 | S32: 0 | T32: =H32*$G$32*8 -> 14720 | U32: =I32*$G$32*8 -> 18400 | V32: =J32*$G$32*8 -> 21160 | W32: =K32*$G$32*8 -> 18400 | X32: =L32*$G$32*8 -> 18400 | Y32: =M32*$G$32*8 -> 20240 | Z32: =N32*$G$32*8 -> 19320 | AA32: =O32*$G$32*8 -> 21160 | ... AE32: =S32*$G$32*8 -> 0
A33: Division 3 | B33: SAVHN009 | C33: OMI | D33: =$A$21&"_"&C33&"_"&"001" -> TB_OMI_001 | E33: 44967 | F33: 45044 | G33: 120 | H33: 0 | I33: =NETWORKDAYS.INTL(E33,VLOOKUP($I$23,$AH$3:$AJ$14,3),"0000011",$AM$3:$AM$17) -> 13 | J33: =$J$24 -> 23 | K33: =NETWORKDAYS.INTL(VLOOKUP($K$23,$AH$3:$AJ$14,2),F33,"0000011",$AM$3:$AM$17) -> 20 | L33: 0 | M33: 0 | N33: 0 | O33: 0 | P33: 0 | Q33: 0 | R33: 0 | S33: 0 | T33: =H33*$G$33*8 -> 0 | U33: =I33*$G$33*8 -> 12480 | V33: =J33*$G$33*8 -> 22080 | W33: =K33*$G$33*8 -> 19200 | X33: =L33*$G$33*8 -> 0 | Y33: =M33*$G$33*8 -> 0 | Z33: =N33*$G$33*8 -> 0 | AA33: =O33*$G$33*8 -> 0 | ... AE33: =S33*$G$33*8 -> 0
A34: Division 3 | B34: SAVHN010 | C34: OMI | D34: =$A$21&"_"&C34&"_"&"001" -> TB_OMI_001 | E34: 44967 | F34: 45044 | G34: 150 | H34: 0 | I34: =NETWORKDAYS.INTL(E34,VLOOKUP($I$23,$AH$3:$AJ$14,3),"0000011",$AM$3:$AM$17) -> 13 | J34: =$J$24 -> 23 | K34: =NETWORKDAYS.INTL(VLOOKUP($K$23,$AH$3:$AJ$14,2),F34,"0000011",$AM$3:$AM$17) -> 20 | L34: 0 | M34: 0 | N34: 0 | O34: 0 | P34: 0 | Q34: 0 | R34: 0 | S34: 0 | T34: =H34*$G$34*8 -> 0 | U34: =I34*$G$34*8 -> 15600 | V34: =J34*$G$34*8 -> 27600 | W34: =K34*$G$34*8 -> 24000 | X34: =L34*$G$34*8 -> 0 | Y34: =M34*$G$34*8 -> 0 | Z34: =N34*$G$34*8 -> 0 | AA34: =O34*$G$34*8 -> 0 | ... AE34: =S34*$G$34*8 -> 0
A38: Tính revenue hàng tháng cho dự án fixed cost
A39: total_revenue | B39: project_contract.contract_revenue
A40: actual_complete_rate_for_month | B40: fixcost_delivery_plan.complete_rate_actual
A41: forcast_complete_rate_for_month | B41: fixcost_delivery_plan.complete_rate
A42: total_member | B42: COUNT("tabProject User".employee_code)
A43: working_days_in_month | B43: SELECT COUNT(*)
B44: FROM generate_series("tabProject User".from_date::date, (date_trunc('month', now()) + interval '1 month - 1 day')::date) AS dates(date)
B45: WHERE EXTRACT(ISODOW FROM date) < 6
B46: AND NOT EXISTS (SELECT 1 FROM holidays WHERE holiday_date = dates.date);
...

Sheet 02. Revenue Target
A1: REVENUE (TARGET)
B2: *Revenue Target is uploaded by PM via Excel
B3: Dashboard Values | C3: _x0008_For | D3: Time | E3: Formula | F3: Description
B4: Target Revenue | C4: All | D4: Feb | E4: =D13 -> 1583000000 | F4: Monthly Target Revenue
B5: Target Revenue | C5: Division 2 | D5: Feb_x000D_ | E5: =D11 -> 53000000 | F5: Monthly Target Revenue
B6: Target Revenue | C6: Division 1 | D6: _x0008_Feb | E6: =D10 -> 1000000000 | F6: Monthly Target Revenue
B8: Target Revenue
B9: Division | C9: Total | D9: T1 | E9: T2 | F9: T3 | G9: T4 | H9: T5 | I9: T6 | J9: T7 | K9: T8 | L9: T9 | M9: T10 | N9: T11 | O9: T12
B10: Division 1 | C10: =SUM(D10:O10) -> 12000000000 | D10: 1000000000 | E10: 1000000000 | F10: 1000000000 | G10: 1000000000 | H10: 1000000000 | I10: 1000000000 | J10: 1000000000 | K10: 1000000000 | L10: 1000000000 | M10: 1000000000 | N10: 1000000000 | O10: 1000000000
B11: Division 2 | C11: =SUM(D11:O11) -> 7715000000 | D11: 53000000 | E11: 630000000 | F11: 420000000 | G11: 550000000 | H11: 670000000 | I11: 880000000 | J11: 900000000 | K11: 720000000 | L11: 680000000 | M11: 690000000 | N11: 890000000 | O11: 632000000
B12: Division 3 | C12: =SUM(D12:O12) -> 9040000000 | D12: 530000000 | E12: 430000000 | F12: 560000000 | G12: 350000000 | H12: 890000000 | I12: 760000000 | J12: 830000000 | K12: 790000000 | L12: 1230000000 | M12: 890000000 | N12: 920000000 | O12: 860000000
B13: All | C13: =SUM(D13:O13) -> 28755000000 | D13: =SUM(D10:D12) -> 1583000000 | E13: =SUM(E10:E12) -> 2060000000 | F13: =SUM(F10:F12) -> 1980000000 | G13: =SUM(G10:G12) -> 1900000000 | H13: =SUM(H10:H12) -> 2560000000 | I13: =SUM(I10:I12) -> 2640000000 | J13: =SUM(J10:J12) -> 2730000000 | K13: =SUM(K10:K12) -> 2510000000 | ... O13: =SUM(O10:O12) -> 2492000000

Sheet 03. Cost Actual
A1: COST (ACTUAL)
A3: Division | B3: Employee Code | C3: Join date | D3: Salary Decision | F3: Customer code | G3: Project code | H3: Project type | J3: Project Duration | L3: Salary | M3: Total Direct Cost | N3: Billable (day/month) | Z3: Bonus rate | AA3: Actual Bonus | AM3: Actual Effort (day/month) | AY3: TOTAL OT | BK3: Cost T1 | BL3: Cost T2 | BM3: Cost T3 | BN3: Cost T4 | BO3: Cost T5 | BP3: Cost T6 | BQ3: Cost T7 | BR3: Cost T8 | BS3: Cost T9 | BT3: Cost T10 | BU3: Cost T11 | BV3: Cost T12
N4: 1 | O4: 2 | P4: 3 | Q4: 4 | R4: 5 | S4: 6 | T4: 7 | U4: 8 | V4: 9 | W4: 10 | X4: 11 | Y4: 12 | AA4: 1 | AB4: 2 | AC4: 3 | AD4: 4 | AE4: 5 | AF4: 6 | AG4: 7 | AH4: 8 | AI4: 9 | AJ4: 10 | AK4: 11 | AL4: 12 | AM4: 1 | AN4: 2 | AO4: 3 | AP4: 4 | AQ4: 5 | AR4: 6 | AS4: 7 | AT4: 8 | AU4: 9 | AV4: 10 | AW4: 11 | AX4: 12 | AY4: 1 | AZ4: 2 | BA4: 3 | BB4: 4 | BC4: 5 | BD4: 6 | BE4: 7 | BF4: 8 | BG4: 9 | BH4: 10 | BI4: 11 | BJ4: 12
D5: Start date | E5: End date | J5: Start date | K5: End date | N5: =NETWORKDAYS.INTL(VLOOKUP(N4,$BX$6:$BZ$14,2),VLOOKUP(N4,$BX$6:$BZ$14,3),"0000011",$CC$6:$CC$15) -> 16 | O5: =NETWORKDAYS.INTL(VLOOKUP(O4,$BX$6:$BZ$14,2),VLOOKUP(O4,$BX$6:$BZ$14,3),"0000011",$CC$6:$CC$15) -> 20 | P5: =NETWORKDAYS.INTL(VLOOKUP(P4,$BX$6:$BZ$14,2),VLOOKUP(P4,$BX$6:$BZ$14,3),"0000011",$CC$6:$CC$15) -> 23 | Q5: =NETWORKDAYS.INTL(VLOOKUP(Q4,$BX$6:$BZ$14,2),VLOOKUP(Q4,$BX$6:$BZ$14,3),"0000011",$CC$6:$CC$15) -> 20 | R5: =NETWORKDAYS.INTL(VLOOKUP(R4,$BX$6:$BZ$14,2),VLOOKUP(R4,$BX$6:$BZ$14,3),"0000011",$CC$6:$CC$15) -> 22 | S5: =NETWORKDAYS.INTL(VLOOKUP(S4,$BX$6:$BZ$14,2),VLOOKUP(S4,$BX$6:$BZ$14,3),"0000011",$CC$6:$CC$15) -> 22 | T5: =NETWORKDAYS.INTL(VLOOKUP(T4,$BX$6:$BZ$14,2),VLOOKUP(T4,$BX$6:$BZ$14,3),"0000011",$CC$6:$CC$15) -> 21 | U5: =NETWORKDAYS.INTL(VLOOKUP(U4,$BX$6:$BZ$14,2),VLOOKUP(U4,$BX$6:$BZ$14,3),"0000011",$CC$6:$CC$15) -> 23 | ... Y5: =NETWORKDAYS.INTL(VLOOKUP(Y4,$BX$6:$BZ$14,2),VLOOKUP(Y4,$BX$6:$BZ$14,3),"0000011",$CC$6:$CC$15) -> 23 | AA5: =NETWORKDAYS.INTL(VLOOKUP(AA4,$BX$6:$BZ$18,2),VLOOKUP(AA4,$BX$6:$BZ$18,3),"0000011",$CC$6:$CC$21) -> 16 | AB5: =NETWORKDAYS.INTL(VLOOKUP(AB4,$BX$6:$BZ$18,2),VLOOKUP(AB4,$BX$6:$BZ$18,3),"0000011",$CC$6:$CC$21) -> 20 | AC5: =NETWORKDAYS.INTL(VLOOKUP(AC4,$BX$6:$BZ$18,2),VLOOKUP(AC4,$BX$6:$BZ$18,3),"0000011",$CC$6:$CC$21) -> 23 | AD5: =NETWORKDAYS.INTL(VLOOKUP(AD4,$BX$6:$BZ$18,2),VLOOKUP(AD4,$BX$6:$BZ$18,3),"0000011",$CC$6:$CC$21) -> 20 | AE5: =NETWORKDAYS.INTL(VLOOKUP(AE4,$BX$6:$BZ$18,2),VLOOKUP(AE4,$BX$6:$BZ$18,3),"0000011",$CC$6:$CC$21) -> 20 | AF5: =NETWORKDAYS.INTL(VLOOKUP(AF4,$BX$6:$BZ$18,2),VLOOKUP(AF4,$BX$6:$BZ$18,3),"0000011",$CC$6:$CC$21) -> 22 | AG5: =NETWORKDAYS.INTL(VLOOKUP(AG4,$BX$6:$BZ$18,2),VLOOKUP(AG4,$BX$6:$BZ$18,3),"0000011",$CC$6:$CC$21) -> 21 | AH5: =NETWORKDAYS.INTL(VLOOKUP(AH4,$BX$6:$BZ$18,2),VLOOKUP(AH4,$BX$6:$BZ$18,3),"0000011",$CC$6:$CC$21) -> 23 | ... BJ5: =NETWORKDAYS.INTL(VLOOKUP(BJ4,$BX$6:$BZ$18,2),VLOOKUP(BJ4,$BX$6:$BZ$18,3),"0000011",$CC$6:$CC$21) -> 21
A6: Division 1 | B6: SAV289 | C6: 43862 | D6: 43862 | E6: 45649 | F6: KGT_x000D_ | G6: =H6&"_"&F6&"_"&"001" -> FC_KGT_x000D__001 | H6: FC | I6: Project based | J6: 44958 | K6: 45000 | L6: 20000000 | M6: 21450000 | N6: 0 | O6: 19 | P6: 10 | Q6: 0 | R6: 0 | S6: 0 | T6: 0 | U6: 0 | V6: 0 | W6: 0 | X6: 0 | Y6: 0 | Z6: 2000000 | AA6: =$Z$6*N6/N5 -> 0 | AB6: =$Z$6*O6/O5 -> 1900000 | AC6: =$Z$6*P6/P5 -> 869565.22 | AD6: =$Z$6*Q6/Q5 -> 0 | AE6: =$Z$6*R6/R5 -> 0 | AF6: =$Z$6*S6/S5 -> 0 | AG6: =$Z$6*T6/T5 -> 0 | AH6: =$Z$6*U6/U5 -> 0 | ... AL6: =$Z$6*Y6/Y5 -> 0 | AM6: =$AM$5 -> 16 | AN6: =$AN$5 -> 20 | AO6: 21 | AP6: =$AP$5 -> 20 | AQ6: =$AQ$5 -> 20 | AR6: =$AR$5 -> 22 | AS6: =$AS$5 -> 21 | AT6: =$AT$5 -> 23 | AU6: =$AU$5 -> 19 | AV6: =$AU$5 -> 19 | AW6: =$AW$5 -> 22 | AX6: =$AU$5 -> 19 | AY6: =VLOOKUP(B6,OT!$B$6:$BG$12,47,0)/$AY$5*L6 -> 0 | AZ6: =VLOOKUP(B6,OT!$B$6:$BG$12,48,0)/$AZ$5*L6 -> 1000000 | BA6: =VLOOKUP(B6,OT!$B$6:$BG$12,48,0)/$BA$5*L6 -> 869565.22 | BB6: =VLOOKUP(B6,OT!$B$6:$BG$12,50,0)/$BB$5*L6 -> 0 | BC6: =VLOOKUP(B6,OT!$B$6:$BG$12,51,0)/$BC$5*L6 -> 0 | BD6: =VLOOKUP(B6,OT!$B$6:$BG$12,52,0)/$BD$5*L6 -> 0 | BE6: =VLOOKUP(B6,OT!$B$6:$BG$12,53,0)/$BE$5*L6 -> 952380.95 | BF6: =VLOOKUP(B6,OT!$B$6:$BG$12,54,0)/$BF$5*L6 -> 0 | BG6: =VLOOKUP(B6,OT!$B$6:$BG$12,55,0)/$BG$5*L6 -> 0 | BH6: =VLOOKUP(B6,OT!$B$6:$BG$12,56,0)/$BH$5*L6 -> 0 | BI6: =VLOOKUP(B6,OT!$B$6:$BG$12,57,0)/$BI$5*L6 -> 0 | BJ6: =VLOOKUP(B6,OT!$B$6:$BG$12,58,0)/$BJ$5*L6 -> 0 | BK6: =($M$6*AM6/AM5)+AA6+AY6 -> 21450000 | BL6: =($M$6*AN6/AN5)+AB6+AZ6 -> 24350000 | BM6: =($M$6*AO6/AO5)+AC6+BA6 -> 21323913 | BN6: =($M$6*AP6/AP5)+AD6+BB6 -> 21450000 | BO6: =($M$6*AQ6/AQ5)+AE6+BC6 -> 21450000 | BP6: =($M$6*AR6/AR5)+AF6+BD6 -> 21450000 | BQ6: =($M$6*AS6/AS5)+AG6+BE6 -> 22402381 | BR6: =($M$6*AT6/AT5)+AH6+BF6 -> 21450000 | ... BV6: =($M$6*AX6/AX5)+AL6+BJ6 -> 19407143 | BX6: 1 | BY6: 44927 | BZ6: 44957 | CB6: New Year Holiday | CC6: 44928
A7: Division 1 | B7: SAV298 | C7: 43863 | D7: 45050 | E7: 45497 | F7: KGT_x000D_ | G7: =H7&"_"&F7&"_"&"001" -> FC_KGT_x000D__001 | H7: FC | I7: Project based | J7: 44958 | K7: 45194 | L7: 26000000 | M7: 28000000 | N7: 0 | O7: 18 | P7: 20 | Q7: 20 | R7: =$R$5 -> 22 | S7: =$S$5 -> 22 | T7: =$T$5 -> 21 | U7: 22 | V7: 14 | W7: 0 | X7: 0 | Y7: 0 | Z7: 2500000 | AA7: =$Z$7*N7/N5 -> 0 | AB7: =$Z$7*O7/O5 -> 2250000 | AC7: =$Z$7*P7/P5 -> 2173913 | AD7: =$Z$7*Q7/Q5 -> 2500000 | AE7: =$Z$7*R7/R5 -> 2500000 | AF7: =$Z$7*S7/S5 -> 2500000 | AG7: =$Z$7*T7/T5 -> 2500000 | AH7: =$Z$7*U7/U5 -> 2391304.3 | ... AL7: =$Z$7*Y7/Y5 -> 0 | AM7: 15 | AN7: =$AN$5 -> 20 | AO7: =$AO$5 -> 23 | AP7: =$AP$5 -> 20 | AQ7: 19 | AR7: 21 | AS7: 20 | AT7: =$AW$5 -> 22 | AU7: =$AU$5 -> 19 | AV7: 20 | AW7: =$AU$5 -> 19 | AX7: 20 | AY7: =VLOOKUP(B7,OT!$B$6:$BG$12,47,0)/$AY$5*L7 -> 1218750 | AZ7: =VLOOKUP(B7,OT!$B$6:$BG$12,48,0)/$AZ$5*L7 -> 1300000 | BA7: =VLOOKUP(B7,OT!$B$6:$BG$12,48,0)/$BA$5*L7 -> 1130434.8 | BB7: =VLOOKUP(B7,OT!$B$6:$BG$12,50,0)/$BB$5*L7 -> 975000 | BC7: =VLOOKUP(B7,OT!$B$6:$BG$12,51,0)/$BC$5*L7 -> 1950000 | BD7: =VLOOKUP(B7,OT!$B$6:$BG$12,52,0)/$BD$5*L7 -> 0 | BE7: =VLOOKUP(B7,OT!$B$6:$BG$12,53,0)/$BE$5*L7 -> 0 | BF7: =VLOOKUP(B7,OT!$B$6:$BG$12,54,0)/$BF$5*L7 -> 0 | BG7: =VLOOKUP(B7,OT!$B$6:$BG$12,55,0)/$BG$5*L7 -> 2052631.6 | BH7: =VLOOKUP(B7,OT!$B$6:$BG$12,56,0)/$BH$5*L7 -> 886363.64 | BI7: =VLOOKUP(B7,OT!$B$6:$BG$12,57,0)/$BI$5*L7 -> 0 | BJ7: =VLOOKUP(B7,OT!$B$6:$BG$12,58,0)/$BJ$5*L7 -> 0 | BK7: =($M$7*AM7/AM5)+AA7+AY7 -> 27468750 | BL7: =($M$7*AN7/AN5)+AB7+AZ7 -> 31550000 | BM7: =($M$7*AO7/AO5)+AC7+BA7 -> 31304348 | BN7: =($M$7*AP7/AP5)+AD7+BB7 -> 31475000 | BO7: =($M$7*AQ7/AQ5)+AE7+BC7 -> 31050000 | BP7: =($M$7*AR7/AR5)+AF7+BD7 -> 29227273 | BQ7: =($M$7*AS7/AS5)+AG7+BE7 -> 29166667 | BR7: =($M$7*AT7/AT5)+AH7+BF7 -> 29173913 | ... BV7: =($M$7*AX7/AX5)+AL7+BJ7 -> 26666667 | BX7: 2 | BY7: 44958 | BZ7: 44985 | CB7: Lunar New Year (Tet) Holidays | CC7: 44946
A8: Division 1 | B8: SAV285 | C8: 43864 | D8: 44927 | E8: 45498 | F8: KGT_x000D_ | G8: =H8&"_"&F8&"_"&"001" -> FC_KGT_x000D__001 | H8: FC | I8: Project based | J8: 44958 | K8: 45194 | L8: 10000000 | M8: 10890000 | N8: 0 | O8: =NETWORKDAYS.INTL(J8,VLOOKUP($O$4,$BX$6:$BZ$18,3),"0000011",$CC$6:$CC$21) -> 20 | P8: 21 | Q8: =$Q$5 -> 20 | R8: =$R$5 -> 22 | S8: =$S$5 -> 22 | T8: =$T$5 -> 21 | U8: =$U$5 -> 23 | V8: =NETWORKDAYS.INTL(VLOOKUP($V$4,$BX$6:$BZ$18,2),K8,"0000011",$CC$6:$CC$21) -> 15 | W8: 0 | X8: 0 | Y8: 0 | Z8: 1000000 | AA8: =$Z$8*N8/N5 -> 0 | AB8: =$Z$8*O8/O5 -> 1000000 | AC8: =$Z$8*P8/P5 -> 913043.48 | AD8: =$Z$8*Q8/Q5 -> 1000000 | AE8: =$Z$8*R8/R5 -> 1000000 | AF8: =$Z$8*S8/S5 -> 1000000 | AG8: =$Z$8*T8/T5 -> 1000000 | AH8: =$Z$8*U8/U5 -> 1000000 | ... AL8: =$Z$8*Y8/Y5 -> 0 | AM8: 16 | AN8: =$AN$5 -> 20 | AO8: =$AO$5 -> 23 | AP8: =$AP$5 -> 20 | AQ8: =$AQ$5 -> 20 | AR8: =$AR$5 -> 22 | AS8: =$AS$5 -> 21 | AT8: =$AT$5 -> 23 | AU8: =$AU$5 -> 19 | AV8: =$AV$5 -> 22 | AW8: =$AW$5 -> 22 | AX8: =$AX$5 -> 21 | AY8: =VLOOKUP(B8,OT!$B$6:$BG$12,47,0)/$AY$5*L8 -> 0 | AZ8: =VLOOKUP(B8,OT!$B$6:$BG$12,48,0)/$AZ$5*L8 -> 0 | BA8: =VLOOKUP(B8,OT!$B$6:$BG$12,48,0)/$BA$5*L8 -> 0 | BB8: =VLOOKUP(B8,OT!$B$6:$BG$12,50,0)/$BB$5*L8 -> 0 | BC8: =VLOOKUP(B8,OT!$B$6:$BG$12,51,0)/$BC$5*L8 -> 0 | BD8: =VLOOKUP(B8,OT!$B$6:$BG$12,52,0)/$BD$5*L8 -> 0 | BE8: =VLOOKUP(B8,OT!$B$6:$BG$12,53,0)/$BE$5*L8 -> 0 | BF8: =VLOOKUP(B8,OT!$B$6:$BG$12,54,0)/$BF$5*L8 -> 326086.96 | BG8: =VLOOKUP(B8,OT!$B$6:$BG$12,55,0)/$BG$5*L8 -> 0 | BH8: =VLOOKUP(B8,OT!$B$6:$BG$12,56,0)/$BH$5*L8 -> 0 | BI8: =VLOOKUP(B8,OT!$B$6:$BG$12,57,0)/$BI$5*L8 -> 0 | BJ8: =VLOOKUP(B8,OT!$B$6:$BG$12,58,0)/$BJ$5*L8 -> 0 | BK8: =($M$8*AM8/AM5)+AA8+AY8 -> 10890000 | BL8: =($M$8*AN8/AN5)+AB8+AZ8 -> 11890000 | BM8: =($M$8*AO8/AO5)+AC8+BA8 -> 11803043 | BN8: =($M$8*AP8/AP5)+AD8+BB8 -> 11890000 | BO8: =($M$8*AQ8/AQ5)+AE8+BC8 -> 11890000 | BP8: =($M$8*AR8/AR5)+AF8+BD8 -> 11890000 | BQ8: =($M$8*AS8/AS5)+AG8+BE8 -> 11890000 | BR8: =($M$8*AT8/AT5)+AH8+BF8 -> 12216087 | ... BV8: =($M$8*AX8/AX5)+AL8+BJ8 -> 10890000 | BX8: 3 | BY8: 44986 | BZ8: 45016 | CC8: 44947
A9: Division 2 | B9: SAV768 | C9: 43865 | D9: 43862 | E9: 45008 | F9: BKT | G9: =H9&"_"&F9&"_"&"001" -> TB_BKT_001 | H9: TB | I9: Team based | J9: 44958 | K9: 45194 | L9: 10000000 | M9: 13890000 | N9: 0 | O9: 19 | P9: =NETWORKDAYS.INTL(VLOOKUP($P$4,$BX$6:$BZ$18,2),E9,"0000011",$CC$6:$CC$21) -> 17 | Q9: 0 | R9: 0 | S9: 0 | T9: 0 | U9: 0 | V9: 0 | W9: 0 | X9: 0 | Y9: 0 | Z9: 3500000 | AA9: =$Z$9*N9/N5 -> 0 | AB9: =$Z$9*O9/O5 -> 3325000 | AC9: =$Z$9*P9/P5 -> 2586956.5 | AD9: =$Z$9*Q9/Q5 -> 0 | AE9: =$Z$9*R9/R5 -> 0 | AF9: =$Z$9*S9/S5 -> 0 | AG9: =$Z$9*T9/T5 -> 0 | AH9: =$Z$9*U9/U5 -> 0 | ... AL9: =$Z$9*Y9/Y5 -> 0 | AM9: 16 | AN9: 19 | AO9: =NETWORKDAYS.INTL(VLOOKUP($AO$4,$BX$6:$BZ$18,2),E9,"0000011",$CC$6:$CC$21) -> 17 | AP9: 0 | AQ9: 0 | AR9: 0 | AS9: 0 | AT9: 0 | AU9: 0 | AV9: 0 | AW9: 0 | AX9: 0 | AY9: =VLOOKUP(B9,OT!$B$6:$BG$12,47,0)/$AY$5*L9 -> 625000 | AZ9: =VLOOKUP(B9,OT!$B$6:$BG$12,48,0)/$AZ$5*L9 -> 0 | BA9: =VLOOKUP(B9,OT!$B$6:$BG$12,48,0)/$BA$5*L9 -> 0 | BB9: =VLOOKUP(B9,OT!$B$6:$BG$12,50,0)/$BB$5*L9 -> 0 | BC9: =VLOOKUP(B9,OT!$B$6:$BG$12,51,0)/$BC$5*L9 -> 500000 | BD9: =VLOOKUP(B9,OT!$B$6:$BG$12,52,0)/$BD$5*L9 -> 0 | BE9: =VLOOKUP(B9,OT!$B$6:$BG$12,53,0)/$BE$5*L9 -> 476190.48 | BF9: =VLOOKUP(B9,OT!$B$6:$BG$12,54,0)/$BF$5*L9 -> 0 | BG9: =VLOOKUP(B9,OT!$B$6:$BG$12,55,0)/$BG$5*L9 -> 0 | BH9: =VLOOKUP(B9,OT!$B$6:$BG$12,56,0)/$BH$5*L9 -> 454545.45 | BI9: =VLOOKUP(B9,OT!$B$6:$BG$12,57,0)/$BI$5*L9 -> 0 | BJ9: =VLOOKUP(B9,OT!$B$6:$BG$12,58,0)/$BJ$5*L9 -> 0 | BK9: =($M$9*AM9/AM5)+AA9+AY9 -> 14515000 | BL9: =($M$9*AN9/AN5)+AB9+AZ9 -> 16520500 | BM9: =($M$9*AO9/AO5)+AC9+BA9 -> 12853478 | BN9: =($M$9*AP9/AP5)+AD9+BB9 -> 0 | BO9: =($M$9*AQ9/AQ5)+AE9+BC9 -> 500000 | BP9: =($M$9*AR9/AR5)+AF9+BD9 -> 0 | BQ9: =($M$9*AS9/AS5)+AG9+BE9 -> 476190.48 | BR9: =($M$9*AT9/AT5)+AH9+BF9 -> 0 | ... BV9: =($M$9*AX9/AX5)+AL9+BJ9 -> 0 | BX9: 4 | BY9: 45017 | BZ9: 45046 | CC9: 44948
A10: Division 2 | B10: SAV768 | C10: 43865 | D10: 45009 | E10: 45375 | F10: BKT | G10: =H10&"_"&F10&"_"&"001" -> TB_BKT_001 | H10: TB | I10: Team based | J10: 44958 | K10: 45194 | L10: 15000000 | M10: 19890000 | N10: 0 | O10: 0 | P10: =NETWORKDAYS.INTL(D10,VLOOKUP($P$4,$BX$6:$BZ$18,3),"0000011",$CC$6:$CC$21) -> 6 | Q10: 19 | R10: 21 | S10: 20 | T10: =$T$5 -> 21 | U10: =$U$5 -> 23 | V10: =NETWORKDAYS.INTL(VLOOKUP($V$4,$BX$6:$BZ$18,2),K10,"0000011",$CC$6:$CC$21) -> 15 | W10: 0 | X10: 0 | Y10: 0 | Z10: 5000000 | AA10: =$Z$10*N10/N5 -> 0 | AB10: =$Z$10*O10/O5 -> 0 | AC10: =$Z$10*P10/P5 -> 1304347.8 | AD10: =$Z$10*Q10/Q5 -> 4750000 | AE10: =$Z$10*R10/R5 -> 4772727.3 | AF10: =$Z$10*S10/S5 -> 4545454.5 | AG10: =$Z$10*T10/T5 -> 5000000 | AH10: =$Z$10*U10/U5 -> 5000000 | ... AL10: =$Z$10*Y10/Y5 -> 0 | AM10: 0 | AN10: 0 | AO10: =NETWORKDAYS.INTL(D10,VLOOKUP($AO$4,$BX$6:$BZ$18,3),"0000011",$CC$6:$CC$21) -> 6 | AP10: =$Q$5 -> 20 | AQ10: =$R$5 -> 22 | AR10: 21 | AS10: =$T$5 -> 21 | AT10: =$U$5 -> 23 | AU10: =$AU$5 -> 19 | AV10: =$AV$5 -> 22 | AW10: =$AW$5 -> 22 | AX10: 20 | AY10: =VLOOKUP(B10,OT!$B$6:$BG$12,47,0)/$AY$5*L10 -> 937500 | AZ10: =VLOOKUP(B10,OT!$B$6:$BG$12,48,0)/$AZ$5*L10 -> 0 | BA10: =VLOOKUP(B10,OT!$B$6:$BG$12,48,0)/$BA$5*L10 -> 0 | BB10: =VLOOKUP(B10,OT!$B$6:$BG$12,50,0)/$BB$5*L10 -> 0 | BC10: =VLOOKUP(B10,OT!$B$6:$BG$12,51,0)/$BC$5*L10 -> 750000 | BD10: =VLOOKUP(B10,OT!$B$6:$BG$12,52,0)/$BD$5*L10 -> 0 | BE10: =VLOOKUP(B10,OT!$B$6:$BG$12,53,0)/$BE$5*L10 -> 714285.71 | BF10: =VLOOKUP(B10,OT!$B$6:$BG$12,54,0)/$BF$5*L10 -> 0 | BG10: =VLOOKUP(B10,OT!$B$6:$BG$12,55,0)/$BG$5*L10 -> 0 | BH10: =VLOOKUP(B10,OT!$B$6:$BG$12,56,0)/$BH$5*L10 -> 681818.18 | BI10: =VLOOKUP(B10,OT!$B$6:$BG$12,57,0)/$BI$5*L10 -> 0 | BJ10: =VLOOKUP(B10,OT!$B$6:$BG$12,58,0)/$BJ$5*L10 -> 0 | BK10: =($M$10*AM10/AM6)+AA10+AY10 -> 937500 | BL10: =($M$10*AN10/AN6)+AB10+AZ10 -> 0 | BM10: =($M$10*AO10/AO6)+AC10+BA10 -> 6987205 | BN10: =($M$10*AP10/AP6)+AD10+BB10 -> 24640000 | BO10: =($M$10*AQ10/AQ6)+AE10+BC10 -> 27401727 | BP10: =($M$10*AR10/AR6)+AF10+BD10 -> 23531364 | BQ10: =($M$10*AS10/AS6)+AG10+BE10 -> 25604286 | BR10: =($M$10*AT10/AT6)+AH10+BF10 -> 24890000 | ... BV10: =($M$10*AX10/AX6)+AL10+BJ10 -> 20936842 | BX10: 4 | BY10: 45017 | BZ10: 45046 | CC10: 44948
A11: Division 3 | B11: SAV657 | C11: 43866 | D11: 44970 | E11: 45500 | F11: OMI | G11: =H11&"_"&F11&"_"&"001" -> TB_OMI_001 | H11: TB | I11: Team based | J11: 44958 | K11: 45194 | L11: 12000000 | M11: 12890000 | N11: 0 | O11: =NETWORKDAYS.INTL(J11,VLOOKUP($O$4,$BX$6:$BZ$18,3),"0000011",$CC$6:$CC$21) -> 20 | P11: =$P$5 -> 23 | Q11: =$Q$5 -> 20 | R11: 20 | S11: =$S$5 -> 22 | T11: =$T$5 -> 21 | U11: =$U$5 -> 23 | V11: =NETWORKDAYS.INTL(VLOOKUP($V$4,$BX$6:$BZ$18,2),K11,"0000011",$CC$6:$CC$21) -> 15 | W11: 0 | X11: 0 | Y11: 0 | Z11: 4000000 | AA11: =$Z$11*N11/N5 -> 0 | AB11: =$Z$11*O11/O5 -> 4000000 | AC11: =$Z$11*P11/P5 -> 4000000 | AD11: =$Z$11*Q11/Q5 -> 4000000 | AE11: =$Z$11*R11/R5 -> 3636363.6 | AF11: =$Z$11*S11/S5 -> 4000000 | AG11: =$Z$11*T11/T5 -> 4000000 | AH11: =$Z$11*U11/U5 -> 4000000 | ... AL11: =$Z$11*Y11/Y5 -> 0 | AM11: 14 | AN11: =$AN$5 -> 20 | AO11: 21 | AP11: =$AP$5 -> 20 | AQ11: =$AU$5 -> 19 | AR11: 20 | AS11: 20 | AT11: =$AW$5 -> 22 | AU11: =$AU$5 -> 19 | AV11: =$AU$5 -> 19 | AW11: 20 | AX11: =$AX$5 -> 21 | AY11: =VLOOKUP(B11,OT!$B$6:$BG$12,47,0)/$AY$5*L11 -> 0 | AZ11: =VLOOKUP(B11,OT!$B$6:$BG$12,48,0)/$AZ$5*L11 -> 600000 | BA11: =VLOOKUP(B11,OT!$B$6:$BG$12,48,0)/$BA$5*L11 -> 521739.13 | BB11: =VLOOKUP(B11,OT!$B$6:$BG$12,50,0)/$BB$5*L11 -> 0 | BC11: =VLOOKUP(B11,OT!$B$6:$BG$12,51,0)/$BC$5*L11 -> 0 | BD11: =VLOOKUP(B11,OT!$B$6:$BG$12,52,0)/$BD$5*L11 -> 0 | BE11: =VLOOKUP(B11,OT!$B$6:$BG$12,53,0)/$BE$5*L11 -> 0 | BF11: =VLOOKUP(B11,OT!$B$6:$BG$12,54,0)/$BF$5*L11 -> 0 | BG11: =VLOOKUP(B11,OT!$B$6:$BG$12,55,0)/$BG$5*L11 -> 0 | BH11: =VLOOKUP(B11,OT!$B$6:$BG$12,56,0)/$BH$5*L11 -> 0 | BI11: =VLOOKUP(B11,OT!$B$6:$BG$12,57,0)/$BI$5*L11 -> 0 | BJ11: =VLOOKUP(B11,OT!$B$6:$BG$12,58,0)/$BJ$5*L11 -> 0 | BK11: =($M$11*AM11/AM5)+AA11+AY11 -> 11278750 | BL11: =($M$11*AN11/AN5)+AB11+AZ11 -> 17490000 | BM11: =($M$11*AO11/AO5)+AC11+BA11 -> 16290870 | BN11: =($M$11*AP11/AP5)+AD11+BB11 -> 16890000 | BO11: =($M$11*AQ11/AQ5)+AE11+BC11 -> 15881864 | BP11: =($M$11*AR11/AR5)+AF11+BD11 -> 15718182 | BQ11: =($M$11*AS11/AS5)+AG11+BE11 -> 16276190 | BR11: =($M$11*AT11/AT5)+AH11+BF11 -> 16329565 | ... BV11: =($M$11*AX11/AX5)+AL11+BJ11 -> 12890000 | BX11: 5 | BY11: 45047 | BZ11: 45077 | CC11: 44949
A12: Division 3 | B12: SAV658 | C12: 43867 | D12: 44970 | E12: 45501 | F12: GYM | G12: =H12&"_"&F12&"_"&"001" -> PS_GYM_001 | H12: PS | I12: Presale | J12: 44927 | K12: 45227 | L12: 10000000 | M12: 13890000 | N12: =NETWORKDAYS.INTL(J12,VLOOKUP($N$4,$BX$6:$BZ$18,3),"0000011",$CC$6:$CC$21) -> 16 | O12: =O5 -> 20 | P12: =$P$5 -> 23 | Q12: 19 | R12: 21 | S12: =$S$5 -> 22 | T12: =$T$5 -> 21 | U12: 22 | V12: 23 | W12: 19 | X12: 0 | Y12: 0 | Z12: 1000000 | AA12: =$Z$12*N12/N5 -> 1000000 | AB12: =$Z$12*O12/O5 -> 1000000 | AC12: =$Z$12*P12/P5 -> 1000000 | AD12: =$Z$12*Q12/Q5 -> 950000 | AE12: =$Z$12*R12/R5 -> 954545.45 | AF12: =$Z$12*S12/S5 -> 1000000 | AG12: =$Z$12*T12/T5 -> 1000000 | AH12: =$Z$12*U12/U5 -> 956521.74 | ... AL12: =$Z$12*Y12/Y5 -> 0 | AM12: =$AM$5 -> 16 | AN12: =$AN$5 -> 20 | AO12: 22 | AP12: =$AP$5 -> 20 | AQ12: =$AQ$5 -> 20 | AR12: =$AR$5 -> 22 | AS12: =$AS$5 -> 21 | AT12: =$AW$5 -> 22 | AU12: =$AU$5 -> 19 | AV12: =$AV$5 -> 22 | AW12: =$AW$5 -> 22 | AX12: 19 | AY12: =VLOOKUP(B12,OT!$B$6:$BG$12,47,0)/$AY$5*L12 -> 0 | AZ12: =VLOOKUP(B12,OT!$B$6:$BG$12,48,0)/$AZ$5*L12 -> 750000 | BA12: =VLOOKUP(B12,OT!$B$6:$BG$12,48,0)/$BA$5*L12 -> 652173.91 | BB12: =VLOOKUP(B12,OT!$B$6:$BG$12,50,0)/$BB$5*L12 -> 0 | BC12: =VLOOKUP(B12,OT!$B$6:$BG$12,51,0)/$BC$5*L12 -> 0 | BD12: =VLOOKUP(B12,OT!$B$6:$BG$12,52,0)/$BD$5*L12 -> 0 | BE12: =VLOOKUP(B12,OT!$B$6:$BG$12,53,0)/$BE$5*L12 -> 0 | BF12: =VLOOKUP(B12,OT!$B$6:$BG$12,54,0)/$BF$5*L12 -> 652173.91 | BG12: =VLOOKUP(B12,OT!$B$6:$BG$12,55,0)/$BG$5*L12 -> 0 | BH12: =VLOOKUP(B12,OT!$B$6:$BG$12,56,0)/$BH$5*L12 -> 0 | BI12: =VLOOKUP(B12,OT!$B$6:$BG$12,57,0)/$BI$5*L12 -> 0 | BJ12: =VLOOKUP(B12,OT!$B$6:$BG$12,58,0)/$BJ$5*L12 -> 0 | BK12: =($M$12*AM12/AM5)+AA12+AY12 -> 14890000 | BL12: =($M$12*AN12/AN5)+AB12+AZ12 -> 15640000 | BM12: =($M$12*AO12/AO5)+AC12+BA12 -> 14938261 | BN12: =($M$12*AP12/AP5)+AD12+BB12 -> 14840000 | BO12: =($M$12*AQ12/AQ5)+AE12+BC12 -> 14844545 | BP12: =($M$12*AR12/AR5)+AF12+BD12 -> 14890000 | BQ12: =($M$12*AS12/AS5)+AG12+BE12 -> 14890000 | BR12: =($M$12*AT12/AT5)+AH12+BF12 -> 14894783 | ... BV12: =($M$12*AX12/AX5)+AL12+BJ12 -> 12567143 | BX12: 6 | BY12: 45078 | BZ12: 45107 | CC12: 44950
BX13: 7 | BY13: 45108 | BZ13: 45138 | CC13: 44951
BX14: 8 | BY14: 45139 | BZ14: 45169 | CC14: 44952
B15: Cost T1 | C15: Cost T2 | D15: Cost T3 | E15: Cost T4 | F15: Cost T5 | G15: Cost T6 | H15: Cost T7 | I15: Cost T8 | J15: Cost T9 | K15: Cost T10 | BX15: 9 | BY15: 45170 | BZ15: 45199 | CB15: Hung Kings Commemoration Day | CC15: 45048
A16: Division 1 | B16: =SUM(BK6:BK8) -> 59808750 | C16: =SUM(BL6:BL8) -> 67790000 | D16: =SUM(BM6:BM8) -> 64431304 | E16: =SUM(AD6:AD8) -> 3500000 | BX16: 10 | BY16: 45200 | BZ16: 45230 | CB16: Victory Day | CC16: 45049
A17: Division 2 | B17: =SUM(BK9:BK10) -> 15452500 | C17: =SUM(BL9:BL10) -> 16520500 | BX17: 11 | BY17: 45231 | BZ17: 45260 | CB17: International Labor Day | CC17: 45047
A18: Division 3 | BX18: 12 | BY18: 45261 | BZ18: 45291 | CB18: National Day | CC18: 45170
A19: All | CC19: 45171
CC20: 45172
CC21: 45173

Sheet 04. Cost Forecast
A1: COST (FORECAST)
A3: Division | B3: Employee Code | C3: Join date | D3: Salary Decision | F3: Customer code | G3: Project code | H3: Project type | J3: Project Duration | L3: Salary | M3: Total Direct Cost | N3: Billable (day/month) | Z3: Bonus rate | AA3: Actual Bonus | AM3: Expected Effort (day/month) | AY3: Cost T1 | AZ3: Cost T2 | BA3: Cost T3 | BB3: Cost T4 | BC3: Cost T5 | BD3: Cost T6 | BE3: Cost T7 | BF3: Cost T8 | BG3: Cost T9 | BH3: Cost T10 | BI3: Cost T11 | BJ3: Cost T12
N4: 1 | O4: 2 | P4: 3 | Q4: 4 | R4: 5 | S4: 6 | T4: 7 | U4: 8 | V4: 9 | W4: 10 | X4: 11 | Y4: 12 | AA4: 1 | AB4: 2 | AC4: 3 | AD4: 4 | AE4: 5 | AF4: 6 | AG4: 7 | AH4: 8 | AI4: 9 | AJ4: 10 | AK4: 11 | AL4: 12 | AM4: 1 | AN4: 2 | AO4: 3 | AP4: 4 | AQ4: 5 | AR4: 6 | AS4: 7 | AT4: 8 | AU4: 9 | AV4: 10 | AW4: 11 | AX4: 12
D5: Start date | E5: End date | J5: Start date | K5: End date | N5: =NETWORKDAYS.INTL(VLOOKUP(N4,$BL$6:$BN$14,2),VLOOKUP(N4,$BL$6:$BN$14,3),"0000011",$BQ$6:$BQ$15) -> 16 | O5: =NETWORKDAYS.INTL(VLOOKUP(O4,$BL$6:$BN$14,2),VLOOKUP(O4,$BL$6:$BN$14,3),"0000011",$BQ$6:$BQ$15) -> 20 | P5: =NETWORKDAYS.INTL(VLOOKUP(P4,$BL$6:$BN$14,2),VLOOKUP(P4,$BL$6:$BN$14,3),"0000011",$BQ$6:$BQ$15) -> 23 | Q5: =NETWORKDAYS.INTL(VLOOKUP(Q4,$BL$6:$BN$14,2),VLOOKUP(Q4,$BL$6:$BN$14,3),"0000011",$BQ$6:$BQ$15) -> 20 | R5: =NETWORKDAYS.INTL(VLOOKUP(R4,$BL$6:$BN$14,2),VLOOKUP(R4,$BL$6:$BN$14,3),"0000011",$BQ$6:$BQ$15) -> 22 | S5: =NETWORKDAYS.INTL(VLOOKUP(S4,$BL$6:$BN$14,2),VLOOKUP(S4,$BL$6:$BN$14,3),"0000011",$BQ$6:$BQ$15) -> 22 | T5: =NETWORKDAYS.INTL(VLOOKUP(T4,$BL$6:$BN$14,2),VLOOKUP(T4,$BL$6:$BN$14,3),"0000011",$BQ$6:$BQ$15) -> 21 | U5: =NETWORKDAYS.INTL(VLOOKUP(U4,$BL$6:$BN$14,2),VLOOKUP(U4,$BL$6:$BN$14,3),"0000011",$BQ$6:$BQ$15) -> 23 | ... Y5: =NETWORKDAYS.INTL(VLOOKUP(Y4,$BL$6:$BN$14,2),VLOOKUP(Y4,$BL$6:$BN$14,3),"0000011",$BQ$6:$BQ$15) -> 23 | AA5: =NETWORKDAYS.INTL(VLOOKUP(AA4,$BL$6:$BN$18,2),VLOOKUP(AA4,$BL$6:$BN$18,3),"0000011",$BQ$6:$BQ$21) -> 16 | AB5: =NETWORKDAYS.INTL(VLOOKUP(AB4,$BL$6:$BN$18,2),VLOOKUP(AB4,$BL$6:$BN$18,3),"0000011",$BQ$6:$BQ$21) -> 20 | AC5: =NETWORKDAYS.INTL(VLOOKUP(AC4,$BL$6:$BN$18,2),VLOOKUP(AC4,$BL$6:$BN$18,3),"0000011",$BQ$6:$BQ$21) -> 23 | AD5: =NETWORKDAYS.INTL(VLOOKUP(AD4,$BL$6:$BN$18,2),VLOOKUP(AD4,$BL$6:$BN$18,3),"0000011",$BQ$6:$BQ$21) -> 20 | AE5: =NETWORKDAYS.INTL(VLOOKUP(AE4,$BL$6:$BN$18,2),VLOOKUP(AE4,$BL$6:$BN$18,3),"0000011",$BQ$6:$BQ$21) -> 20 | AF5: =NETWORKDAYS.INTL(VLOOKUP(AF4,$BL$6:$BN$18,2),VLOOKUP(AF4,$BL$6:$BN$18,3),"0000011",$BQ$6:$BQ$21) -> 22 | AG5: =NETWORKDAYS.INTL(VLOOKUP(AG4,$BL$6:$BN$18,2),VLOOKUP(AG4,$BL$6:$BN$18,3),"0000011",$BQ$6:$BQ$21) -> 21 | AH5: =NETWORKDAYS.INTL(VLOOKUP(AH4,$BL$6:$BN$18,2),VLOOKUP(AH4,$BL$6:$BN$18,3),"0000011",$BQ$6:$BQ$21) -> 23 | ... AX5: =NETWORKDAYS.INTL(VLOOKUP(AX4,$BL$6:$BN$18,2),VLOOKUP(AX4,$BL$6:$BN$18,3),"0000011",$BQ$6:$BQ$21) -> 21
A6: Division 1 | B6: SAV289 | C6: 43862 | D6: 43862 | E6: 45649 | F6: KGT_x000D_ | G6: =H6&"_"&F6&"_"&"001" -> FC_KGT_x000D__001 | H6: FC | I6: Project based | J6: 44958 | K6: 45000 | L6: 20000000 | M6: 21450000 | N6: 0 | O6: =NETWORKDAYS.INTL(J6,VLOOKUP($O$4,$BL$6:$BN$18,3),"0000011",$BQ$6:$BQ$21) -> 20 | P6: =NETWORKDAYS.INTL(K6,VLOOKUP($P$4,$BL$6:$BN$18,3),"0000011",$BQ$6:$BQ$21) -> 13 | Q6: 0 | R6: 0 | S6: 0 | T6: 0 | U6: 0 | V6: 0 | W6: 0 | X6: 0 | Y6: 0 | Z6: 2000000 | AA6: =$Z$6*N6/N5 -> 0 | AB6: =$Z$6*O6/O5 -> 2000000 | AC6: =$Z$6*P6/P5 -> 1130434.8 | AD6: =$Z$6*Q6/Q5 -> 0 | AE6: =$Z$6*R6/R5 -> 0 | AF6: =$Z$6*S6/S5 -> 0 | AG6: =$Z$6*T6/T5 -> 0 | AH6: =$Z$6*U6/U5 -> 0 | ... AL6: =$Z$6*Y6/Y5 -> 0 | AM6: =$AM$5 -> 16 | AN6: =$AN$5 -> 20 | AO6: =$AO$5 -> 23 | AP6: =$AP$5 -> 20 | AQ6: =$AQ$5 -> 20 | AR6: =$AR$5 -> 22 | AS6: =$AS$5 -> 21 | AT6: =$AT$5 -> 23 | AU6: =$AU$5 -> 19 | AV6: =$AV$5 -> 22 | AW6: =$AW$5 -> 22 | AX6: =$AX$5 -> 21 | AY6: =($M$6*AM6/AM5)+AA6 -> 21450000 | AZ6: =($M$6*AN6/AN5)+AB6 -> 23450000 | BA6: =($M$6*AO6/AO5)+AC6 -> 22580435 | BB6: =($M$6*AP6/AP5)+AD6 -> 21450000 | BC6: =($M$6*AQ6/AQ5)+AE6 -> 21450000 | BD6: =($M$6*AR6/AR5)+AF6 -> 21450000 | BE6: =($M$6*AS6/AS5)+AG6 -> 21450000 | BF6: =($M$6*AT6/AT5)+AH6 -> 21450000 | ... BJ6: =($M$6*AX6/AX5)+AL6 -> 21450000 | BL6: 1 | BM6: 44927 | BN6: 44957 | BP6: New Year Holiday | BQ6: 44928
